Workbook

Sheet Forward
A1: IGPM | B1: IPCA | D1: 2015 | E1: 2016 | F1: 2017 | G1: 2018 | H1: 2019 | I1: 2020 | J1: 2021 | K1: 2022 | L1: 2023 | M1: 2024 | N1: 2025 | O1: 2026 | P1: 2027 | Q1: 2028 | R1: 2029 | S1: 2030 | T1: 2031 | U1: 2032 | V1: 2033 | W1: Preços Mercado Livre (I50% - 36 meses futuros) | X1: Preços Mercado Livre - Média Histórica ACL de 36 meses Futuros | Y1: Preços Mercado Livre (I50% - 60 meses futuros) | Z1: Preços Mercado Livre - Média Histórica ACL de 60 meses Futuros | AA1: Ágio Amarela | AB1: Ágio Verm I | AC1: Ágio Verm II | AD1: Break even (Bandeira Verde) | AE1: Break even (Bandeira Amarela) | AF1: Break even (Bandeira Vermelha 1) | AG1: Break even (Bandeira Vermelha 2) | AH1: % Economia (Livre x Cativo) | AI1: A+0 (atual 2026) | AJ1: A+1 (atual 2027) | AK1: A+2 (atual 2028) | AL1: A+3 (atual 2029) | AM1: A+4 (atual 2030)
A86: 0.0182 | B86: 0.0054 | C86: 44562 | K86: 234 | L86: 241 | M86: 214 | N86: =M86-15 -> 199 | O86: 191 | P86: 183 | Q86: =P86-5 -> 178 | R86: =Q86-5 -> 173 | S86: =R86-5 -> 168 | T86: =S86-5 -> 163 | W86: =((13-MONTH($C86))*INDEX($D86:$V86,1,MATCH(YEAR($C86),$D$1:$V$1,0))+12*INDEX($D86:$V86,1,MATCH(YEAR($C86)+1,$D$1:$V$1,0))+12*INDEX($D86:$V86,1,MATCH(YEAR($C86)+2,$D$1:$V$1,0))+(MONTH($C86)-1)*INDEX($D86:$V86,1,MATCH(YEAR($C86)+3,$D$1:$V$1,0)))/36 -> 229.66667 | X86: =AVERAGE($W$2:$W$198) -> 205.00794 | Y86: =((13-MONTH($C86))*INDEX($D86:$V86,1,MATCH(YEAR($C86),$D$1:$V$1,0))+12*INDEX($D86:$V86,1,MATCH(YEAR($C86)+1,$D$1:$V$1,0))+12*INDEX($D86:$V86,1,MATCH(YEAR($C86)+2,$D$1:$V$1,0))+12*INDEX($D86:$V86,1,MATCH(YEAR($C86)+3,$D$1:$V$1,0))+12*INDEX($D86:$V86,1,MATCH(YEAR($C86)+4,$D$1:$V$1,0))+(MONTH($C86)-1)*INDEX($D86:$V86,1,MATCH(YEAR($C86)+5,$D$1:$V$1,0)))/60 -> 215.8 | Z86: =AVERAGE($Y$2:$Y$198) -> 198.26369 | AA86: 29.89 | AB86: 65 | AC86: 97.95 | AD86: 300 | AE86: =$AD86+$AA86 -> 329.89 | AF86: =$AD86+$AB86 -> 365 | AG86: =$AD86+$AC86 -> 397.95 | AH86: =(AD86-W86)/AD86 -> 0.23444444 | AI86: =INDEX($D86:$V86,MATCH(YEAR($C86),$D$1:$V$1,0)) -> 234 | AJ86: =INDEX($D86:$V86,MATCH((YEAR($C86)+1),$D$1:$V$1,0)) -> 241 | AK86: =INDEX($D86:$V86,MATCH((YEAR($C86)+2),$D$1:$V$1,0)) -> 214 | AL86: =INDEX($D86:$V86,MATCH((YEAR($C86)+3),$D$1:$V$1,0)) -> 199 | AM86: =INDEX($D86:$V86,MATCH((YEAR($C86)+4),$D$1:$V$1,0)) -> 191
A87: 0.0183 | B87: 0.0101 | C87: 44593 | K87: 173 | L87: 234 | M87: 219 | N87: 201 | O87: 193 | P87: 185 | Q87: =P87-5 -> 180 | R87: =Q87-5 -> 175 | S87: =R87-5 -> 170 | T87: =S87-5 -> 165 | W87: =((13-MONTH($C87))*INDEX($D87:$V87,1,MATCH(YEAR($C87),$D$1:$V$1,0))+12*INDEX($D87:$V87,1,MATCH(YEAR($C87)+1,$D$1:$V$1,0))+12*INDEX($D87:$V87,1,MATCH(YEAR($C87)+2,$D$1:$V$1,0))+(MONTH($C87)-1)*INDEX($D87:$V87,1,MATCH(YEAR($C87)+3,$D$1:$V$1,0)))/36 -> 209.44444 | X87: =AVERAGE($W$2:$W$198) -> 205.00794 | Y87: =((13-MONTH($C87))*INDEX($D87:$V87,1,MATCH(YEAR($C87),$D$1:$V$1,0))+12*INDEX($D87:$V87,1,MATCH(YEAR($C87)+1,$D$1:$V$1,0))+12*INDEX($D87:$V87,1,MATCH(YEAR($C87)+2,$D$1:$V$1,0))+12*INDEX($D87:$V87,1,MATCH(YEAR($C87)+3,$D$1:$V$1,0))+12*INDEX($D87:$V87,1,MATCH(YEAR($C87)+4,$D$1:$V$1,0))+(MONTH($C87)-1)*INDEX($D87:$V87,1,MATCH(YEAR($C87)+5,$D$1:$V$1,0)))/60 -> 204.2 | Z87: =AVERAGE($Y$2:$Y$198) -> 198.26369 | AA87: 29.89 | AB87: 65 | AC87: 97.95 | AD87: 300 | AE87: =$AD87+$AA87 -> 329.89 | AF87: =$AD87+$AB87 -> 365 | AG87: =$AD87+$AC87 -> 397.95 | AH87: =(AD87-W87)/AD87 -> 0.30185185 | AI87: =INDEX($D87:$V87,MATCH(YEAR($C87),$D$1:$V$1,0)) -> 173 | AJ87: =INDEX($D87:$V87,MATCH((YEAR($C87)+1),$D$1:$V$1,0)) -> 234 | AK87: =INDEX($D87:$V87,MATCH((YEAR($C87)+2),$D$1:$V$1,0)) -> 219 | AL87: =INDEX($D87:$V87,MATCH((YEAR($C87)+3),$D$1:$V$1,0)) -> 201 | AM87: =INDEX($D87:$V87,MATCH((YEAR($C87)+4),$D$1:$V$1,0)) -> 193
A88: 0.0174 | B88: 0.0162 | C88: 44621 | K88: 192 | L88: 258 | M88: 225 | N88: 200 | O88: 192 | P88: 184 | Q88: =P88-5 -> 179 | R88: =Q88-5 -> 174 | S88: =R88-5 -> 169 | T88: =S88-5 -> 164 | W88: =((13-MONTH($C88))*INDEX($D88:$V88,1,MATCH(YEAR($C88),$D$1:$V$1,0))+12*INDEX($D88:$V88,1,MATCH(YEAR($C88)+1,$D$1:$V$1,0))+12*INDEX($D88:$V88,1,MATCH(YEAR($C88)+2,$D$1:$V$1,0))+(MONTH($C88)-1)*INDEX($D88:$V88,1,MATCH(YEAR($C88)+3,$D$1:$V$1,0)))/36 -> 225.44444 | X88: =AVERAGE($W$2:$W$198) -> 205.00794 | Y88: =((13-MONTH($C88))*INDEX($D88:$V88,1,MATCH(YEAR($C88),$D$1:$V$1,0))+12*INDEX($D88:$V88,1,MATCH(YEAR($C88)+1,$D$1:$V$1,0))+12*INDEX($D88:$V88,1,MATCH(YEAR($C88)+2,$D$1:$V$1,0))+12*INDEX($D88:$V88,1,MATCH(YEAR($C88)+3,$D$1:$V$1,0))+12*INDEX($D88:$V88,1,MATCH(YEAR($C88)+4,$D$1:$V$1,0))+(MONTH($C88)-1)*INDEX($D88:$V88,1,MATCH(YEAR($C88)+5,$D$1:$V$1,0)))/60 -> 213.13333 | Z88: =AVERAGE($Y$2:$Y$198) -> 198.26369 | AA88: 29.89 | AB88: 65 | AC88: 97.95 | AD88: 300 | AE88: =$AD88+$AA88 -> 329.89 | AF88: =$AD88+$AB88 -> 365 | AG88: =$AD88+$AC88 -> 397.95 | AH88: =(AD88-W88)/AD88 -> 0.24851852 | AI88: =INDEX($D88:$V88,MATCH(YEAR($C88),$D$1:$V$1,0)) -> 192 | AJ88: =INDEX($D88:$V88,MATCH((YEAR($C88)+1),$D$1:$V$1,0)) -> 258 | AK88: =INDEX($D88:$V88,MATCH((YEAR($C88)+2),$D$1:$V$1,0)) -> 225 | AL88: =INDEX($D88:$V88,MATCH((YEAR($C88)+3),$D$1:$V$1,0)) -> 200 | AM88: =INDEX($D88:$V88,MATCH((YEAR($C88)+4),$D$1:$V$1,0)) -> 192
A89: 0.0141 | B89: 0.0106 | C89: 44652 | K89: 172 | L89: 258 | M89: 233 | N89: 202 | O89: 194 | P89: 186 | Q89: =P89-5 -> 181 | R89: =Q89-5 -> 176 | S89: =R89-5 -> 171 | T89: =S89-5 -> 166 | W89: =((13-MONTH($C89))*INDEX($D89:$V89,1,MATCH(YEAR($C89),$D$1:$V$1,0))+12*INDEX($D89:$V89,1,MATCH(YEAR($C89)+1,$D$1:$V$1,0))+12*INDEX($D89:$V89,1,MATCH(YEAR($C89)+2,$D$1:$V$1,0))+(MONTH($C89)-1)*INDEX($D89:$V89,1,MATCH(YEAR($C89)+3,$D$1:$V$1,0)))/36 -> 223.5 | X89: =AVERAGE($W$2:$W$198) -> 205.00794 | Y89: =((13-MONTH($C89))*INDEX($D89:$V89,1,MATCH(YEAR($C89),$D$1:$V$1,0))+12*INDEX($D89:$V89,1,MATCH(YEAR($C89)+1,$D$1:$V$1,0))+12*INDEX($D89:$V89,1,MATCH(YEAR($C89)+2,$D$1:$V$1,0))+12*INDEX($D89:$V89,1,MATCH(YEAR($C89)+3,$D$1:$V$1,0))+12*INDEX($D89:$V89,1,MATCH(YEAR($C89)+4,$D$1:$V$1,0))+(MONTH($C89)-1)*INDEX($D89:$V89,1,MATCH(YEAR($C89)+5,$D$1:$V$1,0)))/60 -> 212.5 | Z89: =AVERAGE($Y$2:$Y$198) -> 198.26369 | AA89: 29.89 | AB89: 65 | AC89: 97.95 | AD89: 300 | AE89: =$AD89+$AA89 -> 329.89 | AF89: =$AD89+$AB89 -> 365 | AG89: =$AD89+$AC89 -> 397.95 | AH89: =(AD89-W89)/AD89 -> 0.255 | AI89: =INDEX($D89:$V89,MATCH(YEAR($C89),$D$1:$V$1,0)) -> 172 | AJ89: =INDEX($D89:$V89,MATCH((YEAR($C89)+1),$D$1:$V$1,0)) -> 258 | AK89: =INDEX($D89:$V89,MATCH((YEAR($C89)+2),$D$1:$V$1,0)) -> 233 | AL89: =INDEX($D89:$V89,MATCH((YEAR($C89)+3),$D$1:$V$1,0)) -> 202 | AM89: =INDEX($D89:$V89,MATCH((YEAR($C89)+4),$D$1:$V$1,0)) -> 194
A90: 0.0052 | B90: 0.0047 | C90: 44682 | K90: 170 | L90: 235 | M90: 228 | N90: 208 | O90: 200 | P90: 192 | Q90: =P90-5 -> 187 | R90: =Q90-5 -> 182 | S90: =R90-5 -> 177 | T90: =S90-5 -> 172 | W90: =((13-MONTH($C90))*INDEX($D90:$V90,1,MATCH(YEAR($C90),$D$1:$V$1,0))+12*INDEX($D90:$V90,1,MATCH(YEAR($C90)+1,$D$1:$V$1,0))+12*INDEX($D90:$V90,1,MATCH(YEAR($C90)+2,$D$1:$V$1,0))+(MONTH($C90)-1)*INDEX($D90:$V90,1,MATCH(YEAR($C90)+3,$D$1:$V$1,0)))/36 -> 215.22222 | X90: =AVERAGE($W$2:$W$198) -> 205.00794 | Y90: =((13-MONTH($C90))*INDEX($D90:$V90,1,MATCH(YEAR($C90),$D$1:$V$1,0))+12*INDEX($D90:$V90,1,MATCH(YEAR($C90)+1,$D$1:$V$1,0))+12*INDEX($D90:$V90,1,MATCH(YEAR($C90)+2,$D$1:$V$1,0))+12*INDEX($D90:$V90,1,MATCH(YEAR($C90)+3,$D$1:$V$1,0))+12*INDEX($D90:$V90,1,MATCH(YEAR($C90)+4,$D$1:$V$1,0))+(MONTH($C90)-1)*INDEX($D90:$V90,1,MATCH(YEAR($C90)+5,$D$1:$V$1,0)))/60 -> 209.66667 | Z90: =AVERAGE($Y$2:$Y$198) -> 198.26369 | AA90: 29.89 | AB90: 65 | AC90: 97.95 | AD90: 300 | AE90: =$AD90+$AA90 -> 329.89 | AF90: =$AD90+$AB90 -> 365 | AG90: =$AD90+$AC90 -> 397.95 | AH90: =(AD90-W90)/AD90 -> 0.28259259 | AI90: =INDEX($D90:$V90,MATCH(YEAR($C90),$D$1:$V$1,0)) -> 170 | AJ90: =INDEX($D90:$V90,MATCH((YEAR($C90)+1),$D$1:$V$1,0)) -> 235 | AK90: =INDEX($D90:$V90,MATCH((YEAR($C90)+2),$D$1:$V$1,0)) -> 228 | AL90: =INDEX($D90:$V90,MATCH((YEAR($C90)+3),$D$1:$V$1,0)) -> 208 | AM90: =INDEX($D90:$V90,MATCH((YEAR($C90)+4),$D$1:$V$1,0)) -> 200
A91: 0.0059 | B91: 0.0067 | C91: 44713 | K91: 164 | L91: 232 | M91: 223 | N91: 202 | O91: 194 | P91: 186 | Q91: =P91-5 -> 181 | R91: =Q91-5 -> 176 | S91: =R91-5 -> 171 | T91: =S91-5 -> 166 | W91: =((13-MONTH($C91))*INDEX($D91:$V91,1,MATCH(YEAR($C91),$D$1:$V$1,0))+12*INDEX($D91:$V91,1,MATCH(YEAR($C91)+1,$D$1:$V$1,0))+12*INDEX($D91:$V91,1,MATCH(YEAR($C91)+2,$D$1:$V$1,0))+(MONTH($C91)-1)*INDEX($D91:$V91,1,MATCH(YEAR($C91)+3,$D$1:$V$1,0)))/36 -> 211.61111 | X91: =AVERAGE($W$2:$W$198) -> 205.00794 | Y91: =((13-MONTH($C91))*INDEX($D91:$V91,1,MATCH(YEAR($C91),$D$1:$V$1,0))+12*INDEX($D91:$V91,1,MATCH(YEAR($C91)+1,$D$1:$V$1,0))+12*INDEX($D91:$V91,1,MATCH(YEAR($C91)+2,$D$1:$V$1,0))+12*INDEX($D91:$V91,1,MATCH(YEAR($C91)+3,$D$1:$V$1,0))+12*INDEX($D91:$V91,1,MATCH(YEAR($C91)+4,$D$1:$V$1,0))+(MONTH($C91)-1)*INDEX($D91:$V91,1,MATCH(YEAR($C91)+5,$D$1:$V$1,0)))/60 -> 204.83333 | Z91: =AVERAGE($Y$2:$Y$198) -> 198.26369 | AA91: 29.89 | AB91: 65 | AC91: 97.95 | AD91: 300 | AE91: =$AD91+$AA91 -> 329.89 | AF91: =$AD91+$AB91 -> 365 | AG91: =$AD91+$AC91 -> 397.95 | AH91: =(AD91-W91)/AD91 -> 0.29462963 | AI91: =INDEX($D91:$V91,MATCH(YEAR($C91),$D$1:$V$1,0)) -> 164 | AJ91: =INDEX($D91:$V91,MATCH((YEAR($C91)+1),$D$1:$V$1,0)) -> 232 | AK91: =INDEX($D91:$V91,MATCH((YEAR($C91)+2),$D$1:$V$1,0)) -> 223 | AL91: =INDEX($D91:$V91,MATCH((YEAR($C91)+3),$D$1:$V$1,0)) -> 202 | AM91: =INDEX($D91:$V91,MATCH((YEAR($C91)+4),$D$1:$V$1,0)) -> 194
A92: 0.0021 | B92: -0.0068 | C92: 44743 | K92: 97 | L92: 217 | M92: 217 | N92: 203 | O92: 195 | P92: 187 | Q92: =P92-5 -> 182 | R92: =Q92-5 -> 177 | S92: =R92-5 -> 172 | T92: =S92-5 -> 167 | W92: =((13-MONTH($C92))*INDEX($D92:$V92,1,MATCH(YEAR($C92),$D$1:$V$1,0))+12*INDEX($D92:$V92,1,MATCH(YEAR($C92)+1,$D$1:$V$1,0))+12*INDEX($D92:$V92,1,MATCH(YEAR($C92)+2,$D$1:$V$1,0))+(MONTH($C92)-1)*INDEX($D92:$V92,1,MATCH(YEAR($C92)+3,$D$1:$V$1,0)))/36 -> 194.66667 | X92: =AVERAGE($W$2:$W$198) -> 205.00794 | Y92: =((13-MONTH($C92))*INDEX($D92:$V92,1,MATCH(YEAR($C92),$D$1:$V$1,0))+12*INDEX($D92:$V92,1,MATCH(YEAR($C92)+1,$D$1:$V$1,0))+12*INDEX($D92:$V92,1,MATCH(YEAR($C92)+2,$D$1:$V$1,0))+12*INDEX($D92:$V92,1,MATCH(YEAR($C92)+3,$D$1:$V$1,0))+12*INDEX($D92:$V92,1,MATCH(YEAR($C92)+4,$D$1:$V$1,0))+(MONTH($C92)-1)*INDEX($D92:$V92,1,MATCH(YEAR($C92)+5,$D$1:$V$1,0)))/60 -> 194.8 | Z92: =AVERAGE($Y$2:$Y$198) -> 198.26369 | AA92: 29.89 | AB92: 65 | AC92: 97.95 | AD92: 300 | AE92: =$AD92+$AA92 -> 329.89 | AF92: =$AD92+$AB92 -> 365 | AG92: =$AD92+$AC92 -> 397.95 | AH92: =(AD92-W92)/AD92 -> 0.35111111 | AI92: =INDEX($D92:$V92,MATCH(YEAR($C92),$D$1:$V$1,0)) -> 97 | AJ92: =INDEX($D92:$V92,MATCH((YEAR($C92)+1),$D$1:$V$1,0)) -> 217 | AK92: =INDEX($D92:$V92,MATCH((YEAR($C92)+2),$D$1:$V$1,0)) -> 217 | AL92: =INDEX($D92:$V92,MATCH((YEAR($C92)+3),$D$1:$V$1,0)) -> 203 | AM92: =INDEX($D92:$V92,MATCH((YEAR($C92)+4),$D$1:$V$1,0)) -> 195
A93: -0.007 | B93: -0.0036 | C93: 44774 | K93: 99 | L93: 203 | M93: 208 | N93: 198 | O93: 190 | P93: 182 | Q93: =P93-5 -> 177 | R93: =Q93-5 -> 172 | S93: =R93-5 -> 167 | T93: =S93-5 -> 162 | W93: =((13-MONTH($C93))*INDEX($D93:$V93,1,MATCH(YEAR($C93),$D$1:$V$1,0))+12*INDEX($D93:$V93,1,MATCH(YEAR($C93)+1,$D$1:$V$1,0))+12*INDEX($D93:$V93,1,MATCH(YEAR($C93)+2,$D$1:$V$1,0))+(MONTH($C93)-1)*INDEX($D93:$V93,1,MATCH(YEAR($C93)+3,$D$1:$V$1,0)))/36 -> 189.25 | X93: =AVERAGE($W$2:$W$198) -> 205.00794 | Y93: =((13-MONTH($C93))*INDEX($D93:$V93,1,MATCH(YEAR($C93),$D$1:$V$1,0))+12*INDEX($D93:$V93,1,MATCH(YEAR($C93)+1,$D$1:$V$1,0))+12*INDEX($D93:$V93,1,MATCH(YEAR($C93)+2,$D$1:$V$1,0))+12*INDEX($D93:$V93,1,MATCH(YEAR($C93)+3,$D$1:$V$1,0))+12*INDEX($D93:$V93,1,MATCH(YEAR($C93)+4,$D$1:$V$1,0))+(MONTH($C93)-1)*INDEX($D93:$V93,1,MATCH(YEAR($C93)+5,$D$1:$V$1,0)))/60 -> 189.28333 | Z93: =AVERAGE($Y$2:$Y$198) -> 198.26369 | AA93: 29.89 | AB93: 65 | AC93: 97.95 | AD93: 300 | AE93: =$AD93+$AA93 -> 329.89 | AF93: =$AD93+$AB93 -> 365 | AG93: =$AD93+$AC93 -> 397.95 | AH93: =(AD93-W93)/AD93 -> 0.36916667 | AI93: =INDEX($D93:$V93,MATCH(YEAR($C93),$D$1:$V$1,0)) -> 99 | AJ93: =INDEX($D93:$V93,MATCH((YEAR($C93)+1),$D$1:$V$1,0)) -> 203 | AK93: =INDEX($D93:$V93,MATCH((YEAR($C93)+2),$D$1:$V$1,0)) -> 208 | AL93: =INDEX($D93:$V93,MATCH((YEAR($C93)+3),$D$1:$V$1,0)) -> 198 | AM93: =INDEX($D93:$V93,MATCH((YEAR($C93)+4),$D$1:$V$1,0)) -> 190
A94: -0.0095 | B94: -0.0029 | C94: 44805 | K94: 119 | L94: 197 | M94: 204 | N94: 200 | O94: 192 | P94: 184 | Q94: =P94-5 -> 179 | R94: =Q94-5 -> 174 | S94: =R94-5 -> 169 | T94: =S94-5 -> 164 | W94: =((13-MONTH($C94))*INDEX($D94:$V94,1,MATCH(YEAR($C94),$D$1:$V$1,0))+12*INDEX($D94:$V94,1,MATCH(YEAR($C94)+1,$D$1:$V$1,0))+12*INDEX($D94:$V94,1,MATCH(YEAR($C94)+2,$D$1:$V$1,0))+(MONTH($C94)-1)*INDEX($D94:$V94,1,MATCH(YEAR($C94)+3,$D$1:$V$1,0)))/36 -> 191.33333 | X94: =AVERAGE($W$2:$W$198) -> 205.00794 | Y94: =((13-MONTH($C94))*INDEX($D94:$V94,1,MATCH(YEAR($C94),$D$1:$V$1,0))+12*INDEX($D94:$V94,1,MATCH(YEAR($C94)+1,$D$1:$V$1,0))+12*INDEX($D94:$V94,1,MATCH(YEAR($C94)+2,$D$1:$V$1,0))+12*INDEX($D94:$V94,1,MATCH(YEAR($C94)+3,$D$1:$V$1,0))+12*INDEX($D94:$V94,1,MATCH(YEAR($C94)+4,$D$1:$V$1,0))+(MONTH($C94)-1)*INDEX($D94:$V94,1,MATCH(YEAR($C94)+5,$D$1:$V$1,0)))/60 -> 191.06667 | Z94: =AVERAGE($Y$2:$Y$198) -> 198.26369 | AA94: 29.89 | AB94: 65 | AC94: 97.95 | AD94: 300 | AE94: =$AD94+$AA94 -> 329.89 | AF94: =$AD94+$AB94 -> 365 | AG94: =$AD94+$AC94 -> 397.95 | AH94: =(AD94-W94)/AD94 -> 0.36222222 | AI94: =INDEX($D94:$V94,MATCH(YEAR($C94),$D$1:$V$1,0)) -> 119 | AJ94: =INDEX($D94:$V94,MATCH((YEAR($C94)+1),$D$1:$V$1,0)) -> 197 | AK94: =INDEX($D94:$V94,MATCH((YEAR($C94)+2),$D$1:$V$1,0)) -> 204 | AL94: =INDEX($D94:$V94,MATCH((YEAR($C94)+3),$D$1:$V$1,0)) -> 200 | AM94: =INDEX($D94:$V94,MATCH((YEAR($C94)+4),$D$1:$V$1,0)) -> 192
A95: -0.0097 | B95: 0.0059 | C95: 44835 | K95: 95 | L95: 165 | M95: 185 | N95: 185 | O95: 177 | P95: 175 | Q95: =P95-5 -> 170 | R95: =Q95-5 -> 165 | S95: =R95-5 -> 160 | T95: =S95-5 -> 155 | W95: =((13-MONTH($C95))*INDEX($D95:$V95,1,MATCH(YEAR($C95),$D$1:$V$1,0))+12*INDEX($D95:$V95,1,MATCH(YEAR($C95)+1,$D$1:$V$1,0))+12*INDEX($D95:$V95,1,MATCH(YEAR($C95)+2,$D$1:$V$1,0))+(MONTH($C95)-1)*INDEX($D95:$V95,1,MATCH(YEAR($C95)+3,$D$1:$V$1,0)))/36 -> 170.83333 | X95: =AVERAGE($W$2:$W$198) -> 205.00794 | Y95: =((13-MONTH($C95))*INDEX($D95:$V95,1,MATCH(YEAR($C95),$D$1:$V$1,0))+12*INDEX($D95:$V95,1,MATCH(YEAR($C95)+1,$D$1:$V$1,0))+12*INDEX($D95:$V95,1,MATCH(YEAR($C95)+2,$D$1:$V$1,0))+12*INDEX($D95:$V95,1,MATCH(YEAR($C95)+3,$D$1:$V$1,0))+12*INDEX($D95:$V95,1,MATCH(YEAR($C95)+4,$D$1:$V$1,0))+(MONTH($C95)-1)*INDEX($D95:$V95,1,MATCH(YEAR($C95)+5,$D$1:$V$1,0)))/60 -> 173.4 | Z95: =AVERAGE($Y$2:$Y$198) -> 198.26369 | AA95: 29.89 | AB95: 65 | AC95: 97.95 | AD95: 300 | AE95: =$AD95+$AA95 -> 329.89 | AF95: =$AD95+$AB95 -> 365 | AG95: =$AD95+$AC95 -> 397.95 | AH95: =(AD95-W95)/AD95 -> 0.43055556 | AI95: =INDEX($D95:$V95,MATCH(YEAR($C95),$D$1:$V$1,0)) -> 95 | AJ95: =INDEX($D95:$V95,MATCH((YEAR($C95)+1),$D$1:$V$1,0)) -> 165 | AK95: =INDEX($D95:$V95,MATCH((YEAR($C95)+2),$D$1:$V$1,0)) -> 185 | AL95: =INDEX($D95:$V95,MATCH((YEAR($C95)+3),$D$1:$V$1,0)) -> 185 | AM95: =INDEX($D95:$V95,MATCH((YEAR($C95)+4),$D$1:$V$1,0)) -> 177
A96: -0.0056 | B96: 0.0041 | C96: 44866 | K96: 90 | L96: 121 | M96: 163 | N96: 173 | O96: 165 | P96: 175 | Q96: =P96-5 -> 170 | R96: =Q96-5 -> 165 | S96: =R96-5 -> 160 | T96: =S96-5 -> 155 | W96: =((13-MONTH($C96))*INDEX($D96:$V96,1,MATCH(YEAR($C96),$D$1:$V$1,0))+12*INDEX($D96:$V96,1,MATCH(YEAR($C96)+1,$D$1:$V$1,0))+12*INDEX($D96:$V96,1,MATCH(YEAR($C96)+2,$D$1:$V$1,0))+(MONTH($C96)-1)*INDEX($D96:$V96,1,MATCH(YEAR($C96)+3,$D$1:$V$1,0)))/36 -> 147.72222 | X96: =AVERAGE($W$2:$W$198) -> 205.00794 | Y96: =((13-MONTH($C96))*INDEX($D96:$V96,1,MATCH(YEAR($C96),$D$1:$V$1,0))+12*INDEX($D96:$V96,1,MATCH(YEAR($C96)+1,$D$1:$V$1,0))+12*INDEX($D96:$V96,1,MATCH(YEAR($C96)+2,$D$1:$V$1,0))+12*INDEX($D96:$V96,1,MATCH(YEAR($C96)+3,$D$1:$V$1,0))+12*INDEX($D96:$V96,1,MATCH(YEAR($C96)+4,$D$1:$V$1,0))+(MONTH($C96)-1)*INDEX($D96:$V96,1,MATCH(YEAR($C96)+5,$D$1:$V$1,0)))/60 -> 156.56667 | Z96: =AVERAGE($Y$2:$Y$198) -> 198.26369 | AA96: 29.89 | AB96: 65 | AC96: 97.95 | AD96: 300 | AE96: =$AD96+$AA96 -> 329.89 | AF96: =$AD96+$AB96 -> 365 | AG96: =$AD96+$AC96 -> 397.95 | AH96: =(AD96-W96)/AD96 -> 0.50759259 | AI96: =INDEX($D96:$V96,MATCH(YEAR($C96),$D$1:$V$1,0)) -> 90 | AJ96: =INDEX($D96:$V96,MATCH((YEAR($C96)+1),$D$1:$V$1,0)) -> 121 | AK96: =INDEX($D96:$V96,MATCH((YEAR($C96)+2),$D$1:$V$1,0)) -> 163 | AL96: =INDEX($D96:$V96,MATCH((YEAR($C96)+3),$D$1:$V$1,0)) -> 173 | AM96: =INDEX($D96:$V96,MATCH((YEAR($C96)+4),$D$1:$V$1,0)) -> 165
A97: 0.0045 | B97: 0.0062 | C97: 44896 | K97: 91 | L97: 118 | M97: 158 | N97: 170 | O97: 162 | P97: 175 | Q97: =P97-5 -> 170 | R97: =Q97-5 -> 165 | S97: =R97-5 -> 160 | T97: =S97-5 -> 155 | W97: =((13-MONTH($C97))*INDEX($D97:$V97,1,MATCH(YEAR($C97),$D$1:$V$1,0))+12*INDEX($D97:$V97,1,MATCH(YEAR($C97)+1,$D$1:$V$1,0))+12*INDEX($D97:$V97,1,MATCH(YEAR($C97)+2,$D$1:$V$1,0))+(MONTH($C97)-1)*INDEX($D97:$V97,1,MATCH(YEAR($C97)+3,$D$1:$V$1,0)))/36 -> 146.47222 | X97: =AVERAGE($W$2:$W$198) -> 205.00794 | Y97: =((13-MONTH($C97))*INDEX($D97:$V97,1,MATCH(YEAR($C97),$D$1:$V$1,0))+12*INDEX($D97:$V97,1,MATCH(YEAR($C97)+1,$D$1:$V$1,0))+12*INDEX($D97:$V97,1,MATCH(YEAR($C97)+2,$D$1:$V$1,0))+12*INDEX($D97:$V97,1,MATCH(YEAR($C97)+3,$D$1:$V$1,0))+12*INDEX($D97:$V97,1,MATCH(YEAR($C97)+4,$D$1:$V$1,0))+(MONTH($C97)-1)*INDEX($D97:$V97,1,MATCH(YEAR($C97)+5,$D$1:$V$1,0)))/60 -> 155.2 | Z97: =AVERAGE($Y$2:$Y$198) -> 198.26369 | AA97: 29.89 | AB97: 65 | AC97: 97.95 | AD97: 300 | AE97: =$AD97+$AA97 -> 329.89 | AF97: =$AD97+$AB97 -> 365 | AG97: =$AD97+$AC97 -> 397.95 | AH97: =(AD97-W97)/AD97 -> 0.51175926 | AI97: =INDEX($D97:$V97,MATCH(YEAR($C97),$D$1:$V$1,0)) -> 91 | AJ97: =INDEX($D97:$V97,MATCH((YEAR($C97)+1),$D$1:$V$1,0)) -> 118 | AK97: =INDEX($D97:$V97,MATCH((YEAR($C97)+2),$D$1:$V$1,0)) -> 158 | AL97: =INDEX($D97:$V97,MATCH((YEAR($C97)+3),$D$1:$V$1,0)) -> 170 | AM97: =INDEX($D97:$V97,MATCH((YEAR($C97)+4),$D$1:$V$1,0)) -> 162
A98: 0.0021 | B98: 0.0053 | C98: 44927 | L98: 108 | M98: 130 | N98: 145 | O98: 158 | P98: 179 | Q98: =P98-5 -> 174 | R98: =Q98-5 -> 169 | S98: =R98-5 -> 164 | T98: =S98-5 -> 159 | W98: =((13-MONTH($C98))*INDEX($D98:$V98,1,MATCH(YEAR($C98),$D$1:$V$1,0))+12*INDEX($D98:$V98,1,MATCH(YEAR($C98)+1,$D$1:$V$1,0))+12*INDEX($D98:$V98,1,MATCH(YEAR($C98)+2,$D$1:$V$1,0))+(MONTH($C98)-1)*INDEX($D98:$V98,1,MATCH(YEAR($C98)+3,$D$1:$V$1,0)))/36 -> 127.66667 | X98: =AVERAGE($W$2:$W$198) -> 205.00794 | Y98: =((13-MONTH($C98))*INDEX($D98:$V98,1,MATCH(YEAR($C98),$D$1:$V$1,0))+12*INDEX($D98:$V98,1,MATCH(YEAR($C98)+1,$D$1:$V$1,0))+12*INDEX($D98:$V98,1,MATCH(YEAR($C98)+2,$D$1:$V$1,0))+12*INDEX($D98:$V98,1,MATCH(YEAR($C98)+3,$D$1:$V$1,0))+12*INDEX($D98:$V98,1,MATCH(YEAR($C98)+4,$D$1:$V$1,0))+(MONTH($C98)-1)*INDEX($D98:$V98,1,MATCH(YEAR($C98)+5,$D$1:$V$1,0)))/60 -> 144 | Z98: =AVERAGE($Y$2:$Y$198) -> 198.26369 | AA98: 29.89 | AB98: 65 | AC98: 97.95 | AD98: 330 | AE98: =$AD98+$AA98 -> 359.89 | AF98: =$AD98+$AB98 -> 395 | AG98: =$AD98+$AC98 -> 427.95 | AH98: =(AD98-W98)/AD98 -> 0.61313131 | AI98: =INDEX($D98:$V98,MATCH(YEAR($C98),$D$1:$V$1,0)) -> 108 | AJ98: =INDEX($D98:$V98,MATCH((YEAR($C98)+1),$D$1:$V$1,0)) -> 130 | AK98: =INDEX($D98:$V98,MATCH((YEAR($C98)+2),$D$1:$V$1,0)) -> 145 | AL98: =INDEX($D98:$V98,MATCH((YEAR($C98)+3),$D$1:$V$1,0)) -> 158 | AM98: =INDEX($D98:$V98,MATCH((YEAR($C98)+4),$D$1:$V$1,0)) -> 179
A99: -0.0006 | B99: 0.0084 | C99: 44958 | L99: 107 | M99: 121 | N99: 134 | O99: 145 | P99: 179 | Q99: 178 | R99: =Q99-5 -> 173 | S99: =R99-5 -> 168 | T99: =S99-5 -> 163 | W99: =((13-MONTH($C99))*INDEX($D99:$V99,1,MATCH(YEAR($C99),$D$1:$V$1,0))+12*INDEX($D99:$V99,1,MATCH(YEAR($C99)+1,$D$1:$V$1,0))+12*INDEX($D99:$V99,1,MATCH(YEAR($C99)+2,$D$1:$V$1,0))+(MONTH($C99)-1)*INDEX($D99:$V99,1,MATCH(YEAR($C99)+3,$D$1:$V$1,0)))/36 -> 121.72222 | X99: =AVERAGE($W$2:$W$198) -> 205.00794 | Y99: =((13-MONTH($C99))*INDEX($D99:$V99,1,MATCH(YEAR($C99),$D$1:$V$1,0))+12*INDEX($D99:$V99,1,MATCH(YEAR($C99)+1,$D$1:$V$1,0))+12*INDEX($D99:$V99,1,MATCH(YEAR($C99)+2,$D$1:$V$1,0))+12*INDEX($D99:$V99,1,MATCH(YEAR($C99)+3,$D$1:$V$1,0))+12*INDEX($D99:$V99,1,MATCH(YEAR($C99)+4,$D$1:$V$1,0))+(MONTH($C99)-1)*INDEX($D99:$V99,1,MATCH(YEAR($C99)+5,$D$1:$V$1,0)))/60 -> 138.38333 | Z99: =AVERAGE($Y$2:$Y$198) -> 198.26369 | AA99: 29.89 | AB99: 65 | AC99: 97.95 | AD99: 330 | AE99: =$AD99+$AA99 -> 359.89 | AF99: =$AD99+$AB99 -> 395 | AG99: =$AD99+$AC99 -> 427.95 | AH99: =(AD99-W99)/AD99 -> 0.63114478 | AI99: =INDEX($D99:$V99,MATCH(YEAR($C99),$D$1:$V$1,0)) -> 107 | AJ99: =INDEX($D99:$V99,MATCH((YEAR($C99)+1),$D$1:$V$1,0)) -> 121 | AK99: =INDEX($D99:$V99,MATCH((YEAR($C99)+2),$D$1:$V$1,0)) -> 134 | AL99: =INDEX($D99:$V99,MATCH((YEAR($C99)+3),$D$1:$V$1,0)) -> 145 | AM99: =INDEX($D99:$V99,MATCH((YEAR($C99)+4),$D$1:$V$1,0)) -> 179
A100: 0.0005 | B100: 0.0071 | C100: 44986 | L100: 103 | M100: 116 | N100: 130 | O100: 137 | P100: 159 | Q100: 171 | R100: =Q100-5 -> 166 | S100: =R100-5 -> 161 | T100: =S100-5 -> 156 | W100: =((13-MONTH($C100))*INDEX($D100:$V100,1,MATCH(YEAR($C100),$D$1:$V$1,0))+12*INDEX($D100:$V100,1,MATCH(YEAR($C100)+1,$D$1:$V$1,0))+12*INDEX($D100:$V100,1,MATCH(YEAR($C100)+2,$D$1:$V$1,0))+(MONTH($C100)-1)*INDEX($D100:$V100,1,MATCH(YEAR($C100)+3,$D$1:$V$1,0)))/36 -> 118.22222 | X100: =AVERAGE($W$2:$W$198) -> 205.00794 | Y100: =((13-MONTH($C100))*INDEX($D100:$V100,1,MATCH(YEAR($C100),$D$1:$V$1,0))+12*INDEX($D100:$V100,1,MATCH(YEAR($C100)+1,$D$1:$V$1,0))+12*INDEX($D100:$V100,1,MATCH(YEAR($C100)+2,$D$1:$V$1,0))+12*INDEX($D100:$V100,1,MATCH(YEAR($C100)+3,$D$1:$V$1,0))+12*INDEX($D100:$V100,1,MATCH(YEAR($C100)+4,$D$1:$V$1,0))+(MONTH($C100)-1)*INDEX($D100:$V100,1,MATCH(YEAR($C100)+5,$D$1:$V$1,0)))/60 -> 131.26667 | Z100: =AVERAGE($Y$2:$Y$198) -> 198.26369 | AA100: 29.89 | AB100: 65 | AC100: 97.95 | AD100: 330 | AE100: =$AD100+$AA100 -> 359.89 | AF100: =$AD100+$AB100 -> 395 | AG100: =$AD100+$AC100 -> 427.95 | AH100: =(AD100-W100)/AD100 -> 0.64175084 | AI100: =INDEX($D100:$V100,MATCH(YEAR($C100),$D$1:$V$1,0)) -> 103 | AJ100: =INDEX($D100:$V100,MATCH((YEAR($C100)+1),$D$1:$V$1,0)) -> 116 | AK100: =INDEX($D100:$V100,MATCH((YEAR($C100)+2),$D$1:$V$1,0)) -> 130 | AL100: =INDEX($D100:$V100,MATCH((YEAR($C100)+3),$D$1:$V$1,0)) -> 137 | AM100: =INDEX($D100:$V100,MATCH((YEAR($C100)+4),$D$1:$V$1,0)) -> 159
A101: -0.0095 | B101: 0.0057 | C101: 45017 | L101: 101 | M101: 103 | N101: 115 | O101: 128 | P101: 149 | Q101: 165 | R101: =Q101-2 -> 163 | S101: =R101-2 -> 161 | T101: =S101-2 -> 159 | W101: =((13-MONTH($C101))*INDEX($D101:$V101,1,MATCH(YEAR($C101),$D$1:$V$1,0))+12*INDEX($D101:$V101,1,MATCH(YEAR($C101)+1,$D$1:$V$1,0))+12*INDEX($D101:$V101,1,MATCH(YEAR($C101)+2,$D$1:$V$1,0))+(MONTH($C101)-1)*INDEX($D101:$V101,1,MATCH(YEAR($C101)+3,$D$1:$V$1,0)))/36 -> 108.58333 | X101: =AVERAGE($W$2:$W$198) -> 205.00794 | Y101: =((13-MONTH($C101))*INDEX($D101:$V101,1,MATCH(YEAR($C101),$D$1:$V$1,0))+12*INDEX($D101:$V101,1,MATCH(YEAR($C101)+1,$D$1:$V$1,0))+12*INDEX($D101:$V101,1,MATCH(YEAR($C101)+2,$D$1:$V$1,0))+12*INDEX($D101:$V101,1,MATCH(YEAR($C101)+3,$D$1:$V$1,0))+12*INDEX($D101:$V101,1,MATCH(YEAR($C101)+4,$D$1:$V$1,0))+(MONTH($C101)-1)*INDEX($D101:$V101,1,MATCH(YEAR($C101)+5,$D$1:$V$1,0)))/60 -> 122.4 | Z101: =AVERAGE($Y$2:$Y$198) -> 198.26369 | AA101: 29.89 | AB101: 65 | AC101: 97.95 | AD101: 330 | AE101: =$AD101+$AA101 -> 359.89 | AF101: =$AD101+$AB101 -> 395 | AG101: =$AD101+$AC101 -> 427.95 | AH101: =(AD101-W101)/AD101 -> 0.6709596 | AI101: =INDEX($D101:$V101,MATCH(YEAR($C101),$D$1:$V$1,0)) -> 101 | AJ101: =INDEX($D101:$V101,MATCH((YEAR($C101)+1),$D$1:$V$1,0)) -> 103 | AK101: =INDEX($D101:$V101,MATCH((YEAR($C101)+2),$D$1:$V$1,0)) -> 115 | AL101: =INDEX($D101:$V101,MATCH((YEAR($C101)+3),$D$1:$V$1,0)) -> 128 | AM101: =INDEX($D101:$V101,MATCH((YEAR($C101)+4),$D$1:$V$1,0)) -> 149
A102: -0.0184 | B102: 0.0023 | C102: 45047 | L102: 105 | M102: 106 | N102: 119 | O102: 130 | P102: 145 | Q102: 160 | R102: =Q102-2 -> 158 | S102: =R102-2 -> 156 | T102: =S102-2 -> 154 | W102: =((13-MONTH($C102))*INDEX($D102:$V102,1,MATCH(YEAR($C102),$D$1:$V$1,0))+12*INDEX($D102:$V102,1,MATCH(YEAR($C102)+1,$D$1:$V$1,0))+12*INDEX($D102:$V102,1,MATCH(YEAR($C102)+2,$D$1:$V$1,0))+(MONTH($C102)-1)*INDEX($D102:$V102,1,MATCH(YEAR($C102)+3,$D$1:$V$1,0)))/36 -> 112.77778 | X102: =AVERAGE($W$2:$W$198) -> 205.00794 | Y102: =((13-MONTH($C102))*INDEX($D102:$V102,1,MATCH(YEAR($C102),$D$1:$V$1,0))+12*INDEX($D102:$V102,1,MATCH(YEAR($C102)+1,$D$1:$V$1,0))+12*INDEX($D102:$V102,1,MATCH(YEAR($C102)+2,$D$1:$V$1,0))+12*INDEX($D102:$V102,1,MATCH(YEAR($C102)+3,$D$1:$V$1,0))+12*INDEX($D102:$V102,1,MATCH(YEAR($C102)+4,$D$1:$V$1,0))+(MONTH($C102)-1)*INDEX($D102:$V102,1,MATCH(YEAR($C102)+5,$D$1:$V$1,0)))/60 -> 124.66667 | Z102: =AVERAGE($Y$2:$Y$198) -> 198.26369 | AA102: 29.89 | AB102: 65 | AC102: 97.95 | AD102: 330 | AE102: =$AD102+$AA102 -> 359.89 | AF102: =$AD102+$AB102 -> 395 | AG102: =$AD102+$AC102 -> 427.95 | AH102: =(AD102-W102)/AD102 -> 0.65824916 | AI102: =INDEX($D102:$V102,MATCH(YEAR($C102),$D$1:$V$1,0)) -> 105 | AJ102: =INDEX($D102:$V102,MATCH((YEAR($C102)+1),$D$1:$V$1,0)) -> 106 | AK102: =INDEX($D102:$V102,MATCH((YEAR($C102)+2),$D$1:$V$1,0)) -> 119 | AL102: =INDEX($D102:$V102,MATCH((YEAR($C102)+3),$D$1:$V$1,0)) -> 130 | AM102: =INDEX($D102:$V102,MATCH((YEAR($C102)+4),$D$1:$V$1,0)) -> 145
A103: -0.0193 | B103: -0.0008 | C103: 45078 | L103: 105 | M103: 107 | N103: 121 | O103: 131 | P103: 139 | Q103: 156 | R103: =Q103-2 -> 154 | S103: =R103-2 -> 152 | T103: =S103-2 -> 150 | W103: =((13-MONTH($C103))*INDEX($D103:$V103,1,MATCH(YEAR($C103),$D$1:$V$1,0))+12*INDEX($D103:$V103,1,MATCH(YEAR($C103)+1,$D$1:$V$1,0))+12*INDEX($D103:$V103,1,MATCH(YEAR($C103)+2,$D$1:$V$1,0))+(MONTH($C103)-1)*INDEX($D103:$V103,1,MATCH(YEAR($C103)+3,$D$1:$V$1,0)))/36 -> 114.61111 | X103: =AVERAGE($W$2:$W$198) -> 205.00794 | Y103: =((13-MONTH($C103))*INDEX($D103:$V103,1,MATCH(YEAR($C103),$D$1:$V$1,0))+12*INDEX($D103:$V103,1,MATCH(YEAR($C103)+1,$D$1:$V$1,0))+12*INDEX($D103:$V103,1,MATCH(YEAR($C103)+2,$D$1:$V$1,0))+12*INDEX($D103:$V103,1,MATCH(YEAR($C103)+3,$D$1:$V$1,0))+12*INDEX($D103:$V103,1,MATCH(YEAR($C103)+4,$D$1:$V$1,0))+(MONTH($C103)-1)*INDEX($D103:$V103,1,MATCH(YEAR($C103)+5,$D$1:$V$1,0)))/60 -> 124.85 | Z103: =AVERAGE($Y$2:$Y$198) -> 198.26369 | AA103: 29.89 | AB103: 65 | AC103: 97.95 | AD103: 330 | AE103: =$AD103+$AA103 -> 359.89 | AF103: =$AD103+$AB103 -> 395 | AG103: =$AD103+$AC103 -> 427.95 | AH103: =(AD103-W103)/AD103 -> 0.6526936 | AI103: =INDEX($D103:$V103,MATCH(YEAR($C103),$D$1:$V$1,0)) -> 105 | AJ103: =INDEX($D103:$V103,MATCH((YEAR($C103)+1),$D$1:$V$1,0)) -> 107 | AK103: =INDEX($D103:$V103,MATCH((YEAR($C103)+2),$D$1:$V$1,0)) -> 121 | AL103: =INDEX($D103:$V103,MATCH((YEAR($C103)+3),$D$1:$V$1,0)) -> 131 | AM103: =INDEX($D103:$V103,MATCH((YEAR($C103)+4),$D$1:$V$1,0)) -> 139
A104: -0.0072 | B104: 0.0012 | C104: 45108 | L104: 108 | M104: 110 | N104: 123 | O104: 130 | P104: 139 | Q104: 152 | R104: =Q104-2 -> 150 | S104: =R104-2 -> 148 | T104: =S104-2 -> 146 | W104: =((13-MONTH($C104))*INDEX($D104:$V104,1,MATCH(YEAR($C104),$D$1:$V$1,0))+12*INDEX($D104:$V104,1,MATCH(YEAR($C104)+1,$D$1:$V$1,0))+12*INDEX($D104:$V104,1,MATCH(YEAR($C104)+2,$D$1:$V$1,0))+(MONTH($C104)-1)*INDEX($D104:$V104,1,MATCH(YEAR($C104)+3,$D$1:$V$1,0)))/36 -> 117.33333 | X104: =AVERAGE($W$2:$W$198) -> 205.00794 | Y104: =((13-MONTH($C104))*INDEX($D104:$V104,1,MATCH(YEAR($C104),$D$1:$V$1,0))+12*INDEX($D104:$V104,1,MATCH(YEAR($C104)+1,$D$1:$V$1,0))+12*INDEX($D104:$V104,1,MATCH(YEAR($C104)+2,$D$1:$V$1,0))+12*INDEX($D104:$V104,1,MATCH(YEAR($C104)+3,$D$1:$V$1,0))+12*INDEX($D104:$V104,1,MATCH(YEAR($C104)+4,$D$1:$V$1,0))+(MONTH($C104)-1)*INDEX($D104:$V104,1,MATCH(YEAR($C104)+5,$D$1:$V$1,0)))/60 -> 126.4 | Z104: =AVERAGE($Y$2:$Y$198) -> 198.26369 | AA104: 29.89 | AB104: 65 | AC104: 97.95 | AD104: 330 | AE104: =$AD104+$AA104 -> 359.89 | AF104: =$AD104+$AB104 -> 395 | AG104: =$AD104+$AC104 -> 427.95 | AH104: =(AD104-W104)/AD104 -> 0.64444444 | AI104: =INDEX($D104:$V104,MATCH(YEAR($C104),$D$1:$V$1,0)) -> 108 | AJ104: =INDEX($D104:$V104,MATCH((YEAR($C104)+1),$D$1:$V$1,0)) -> 110 | AK104: =INDEX($D104:$V104,MATCH((YEAR($C104)+2),$D$1:$V$1,0)) -> 123 | AL104: =INDEX($D104:$V104,MATCH((YEAR($C104)+3),$D$1:$V$1,0)) -> 130 | AM104: =INDEX($D104:$V104,MATCH((YEAR($C104)+4),$D$1:$V$1,0)) -> 139
A105: -0.0014 | B105: 0.0029 | C105: 45139 | L105: 111 | M105: 107 | N105: 122 | O105: 130 | P105: 139 | Q105: 152 | R105: =Q105-2 -> 150 | S105: =R105-2 -> 148 | T105: =S105-2 -> 146 | W105: =((13-MONTH($C105))*INDEX($D105:$V105,1,MATCH(YEAR($C105),$D$1:$V$1,0))+12*INDEX($D105:$V105,1,MATCH(YEAR($C105)+1,$D$1:$V$1,0))+12*INDEX($D105:$V105,1,MATCH(YEAR($C105)+2,$D$1:$V$1,0))+(MONTH($C105)-1)*INDEX($D105:$V105,1,MATCH(YEAR($C105)+3,$D$1:$V$1,0)))/36 -> 117.02778 | X105: =AVERAGE($W$2:$W$198) -> 205.00794 | Y105: =((13-MONTH($C105))*INDEX($D105:$V105,1,MATCH(YEAR($C105),$D$1:$V$1,0))+12*INDEX($D105:$V105,1,MATCH(YEAR($C105)+1,$D$1:$V$1,0))+12*INDEX($D105:$V105,1,MATCH(YEAR($C105)+2,$D$1:$V$1,0))+12*INDEX($D105:$V105,1,MATCH(YEAR($C105)+3,$D$1:$V$1,0))+12*INDEX($D105:$V105,1,MATCH(YEAR($C105)+4,$D$1:$V$1,0))+(MONTH($C105)-1)*INDEX($D105:$V105,1,MATCH(YEAR($C105)+5,$D$1:$V$1,0)))/60 -> 126.58333 | Z105: =AVERAGE($Y$2:$Y$198) -> 198.26369 | AA105: 29.89 | AB105: 65 | AC105: 97.95 | AD105: 330 | AE105: =$AD105+$AA105 -> 359.89 | AF105: =$AD105+$AB105 -> 395 | AG105: =$AD105+$AC105 -> 427.95 | AH105: =(AD105-W105)/AD105 -> 0.64537037 | AI105: =INDEX($D105:$V105,MATCH(YEAR($C105),$D$1:$V$1,0)) -> 111 | AJ105: =INDEX($D105:$V105,MATCH((YEAR($C105)+1),$D$1:$V$1,0)) -> 107 | AK105: =INDEX($D105:$V105,MATCH((YEAR($C105)+2),$D$1:$V$1,0)) -> 122 | AL105: =INDEX($D105:$V105,MATCH((YEAR($C105)+3),$D$1:$V$1,0)) -> 130 | AM105: =INDEX($D105:$V105,MATCH((YEAR($C105)+4),$D$1:$V$1,0)) -> 139
A106: 0.0037 | B106: 0.0026 | C106: 45170 | L106: 108 | M106: 103 | N106: 116 | O106: 125 | P106: 139 | Q106: 152 | R106: =Q106-2 -> 150 | S106: =R106-2 -> 148 | T106: =S106-2 -> 146 | W106: =((13-MONTH($C106))*INDEX($D106:$V106,1,MATCH(YEAR($C106),$D$1:$V$1,0))+12*INDEX($D106:$V106,1,MATCH(YEAR($C106)+1,$D$1:$V$1,0))+12*INDEX($D106:$V106,1,MATCH(YEAR($C106)+2,$D$1:$V$1,0))+(MONTH($C106)-1)*INDEX($D106:$V106,1,MATCH(YEAR($C106)+3,$D$1:$V$1,0)))/36 -> 112.77778 | X106: =AVERAGE($W$2:$W$198) -> 205.00794 | Y106: =((13-MONTH($C106))*INDEX($D106:$V106,1,MATCH(YEAR($C106),$D$1:$V$1,0))+12*INDEX($D106:$V106,1,MATCH(YEAR($C106)+1,$D$1:$V$1,0))+12*INDEX($D106:$V106,1,MATCH(YEAR($C106)+2,$D$1:$V$1,0))+12*INDEX($D106:$V106,1,MATCH(YEAR($C106)+3,$D$1:$V$1,0))+12*INDEX($D106:$V106,1,MATCH(YEAR($C106)+4,$D$1:$V$1,0))+(MONTH($C106)-1)*INDEX($D106:$V106,1,MATCH(YEAR($C106)+5,$D$1:$V$1,0)))/60 -> 124.06667 | Z106: =AVERAGE($Y$2:$Y$198) -> 198.26369 | AA106: 29.89 | AB106: 65 | AC106: 97.95 | AD106: 330 | AE106: =$AD106+$AA106 -> 359.89 | AF106: =$AD106+$AB106 -> 395 | AG106: =$AD106+$AC106 -> 427.95 | AH106: =(AD106-W106)/AD106 -> 0.65824916 | AI106: =INDEX($D106:$V106,MATCH(YEAR($C106),$D$1:$V$1,0)) -> 108 | AJ106: =INDEX($D106:$V106,MATCH((YEAR($C106)+1),$D$1:$V$1,0)) -> 103 | AK106: =INDEX($D106:$V106,MATCH((YEAR($C106)+2),$D$1:$V$1,0)) -> 116 | AL106: =INDEX($D106:$V106,MATCH((YEAR($C106)+3),$D$1:$V$1,0)) -> 125 | AM106: =INDEX($D106:$V106,MATCH((YEAR($C106)+4),$D$1:$V$1,0)) -> 139
A107: 0.005 | B107: 0.0024 | C107: 45200 | L107: 110 | M107: 104 | N107: 120 | O107: 130 | P107: 137 | Q107: 150 | R107: =Q107-2 -> 148 | S107: =R107-2 -> 146 | T107: =S107-2 -> 144 | W107: =((13-MONTH($C107))*INDEX($D107:$V107,1,MATCH(YEAR($C107),$D$1:$V$1,0))+12*INDEX($D107:$V107,1,MATCH(YEAR($C107)+1,$D$1:$V$1,0))+12*INDEX($D107:$V107,1,MATCH(YEAR($C107)+2,$D$1:$V$1,0))+(MONTH($C107)-1)*INDEX($D107:$V107,1,MATCH(YEAR($C107)+3,$D$1:$V$1,0)))/36 -> 116.33333 | X107: =AVERAGE($W$2:$W$198) -> 205.00794 | Y107: =((13-MONTH($C107))*INDEX($D107:$V107,1,MATCH(YEAR($C107),$D$1:$V$1,0))+12*INDEX($D107:$V107,1,MATCH(YEAR($C107)+1,$D$1:$V$1,0))+12*INDEX($D107:$V107,1,MATCH(YEAR($C107)+2,$D$1:$V$1,0))+12*INDEX($D107:$V107,1,MATCH(YEAR($C107)+3,$D$1:$V$1,0))+12*INDEX($D107:$V107,1,MATCH(YEAR($C107)+4,$D$1:$V$1,0))+(MONTH($C107)-1)*INDEX($D107:$V107,1,MATCH(YEAR($C107)+5,$D$1:$V$1,0)))/60 -> 126.2 | Z107: =AVERAGE($Y$2:$Y$198) -> 198.26369 | AA107: 29.89 | AB107: 65 | AC107: 97.95 | AD107: 330 | AE107: =$AD107+$AA107 -> 359.89 | AF107: =$AD107+$AB107 -> 395 | AG107: =$AD107+$AC107 -> 427.95 | AH107: =(AD107-W107)/AD107 -> 0.64747475 | AI107: =INDEX($D107:$V107,MATCH(YEAR($C107),$D$1:$V$1,0)) -> 110 | AJ107: =INDEX($D107:$V107,MATCH((YEAR($C107)+1),$D$1:$V$1,0)) -> 104 | AK107: =INDEX($D107:$V107,MATCH((YEAR($C107)+2),$D$1:$V$1,0)) -> 120 | AL107: =INDEX($D107:$V107,MATCH((YEAR($C107)+3),$D$1:$V$1,0)) -> 130 | AM107: =INDEX($D107:$V107,MATCH((YEAR($C107)+4),$D$1:$V$1,0)) -> 137
A108: 0.0059 | B108: 0.0028 | C108: 45231 | L108: 110 | M108: 117 | N108: 129 | O108: 139 | P108: 137 | Q108: 150 | R108: =Q108-2 -> 148 | S108: =R108-2 -> 146 | T108: =S108-2 -> 144 | W108: =((13-MONTH($C108))*INDEX($D108:$V108,1,MATCH(YEAR($C108),$D$1:$V$1,0))+12*INDEX($D108:$V108,1,MATCH(YEAR($C108)+1,$D$1:$V$1,0))+12*INDEX($D108:$V108,1,MATCH(YEAR($C108)+2,$D$1:$V$1,0))+(MONTH($C108)-1)*INDEX($D108:$V108,1,MATCH(YEAR($C108)+3,$D$1:$V$1,0)))/36 -> 126.72222 | X108: =AVERAGE($W$2:$W$198) -> 205.00794 | Y108: =((13-MONTH($C108))*INDEX($D108:$V108,1,MATCH(YEAR($C108),$D$1:$V$1,0))+12*INDEX($D108:$V108,1,MATCH(YEAR($C108)+1,$D$1:$V$1,0))+12*INDEX($D108:$V108,1,MATCH(YEAR($C108)+2,$D$1:$V$1,0))+12*INDEX($D108:$V108,1,MATCH(YEAR($C108)+3,$D$1:$V$1,0))+12*INDEX($D108:$V108,1,MATCH(YEAR($C108)+4,$D$1:$V$1,0))+(MONTH($C108)-1)*INDEX($D108:$V108,1,MATCH(YEAR($C108)+5,$D$1:$V$1,0)))/60 -> 133.06667 | Z108: =AVERAGE($Y$2:$Y$198) -> 198.26369 | AA108: 29.89 | AB108: 65 | AC108: 97.95 | AD108: 330 | AE108: =$AD108+$AA108 -> 359.89 | AF108: =$AD108+$AB108 -> 395 | AG108: =$AD108+$AC108 -> 427.95 | AH108: =(AD108-W108)/AD108 -> 0.61599327 | AI108: =INDEX($D108:$V108,MATCH(YEAR($C108),$D$1:$V$1,0)) -> 110 | AJ108: =INDEX($D108:$V108,MATCH((YEAR($C108)+1),$D$1:$V$1,0)) -> 117 | AK108: =INDEX($D108:$V108,MATCH((YEAR($C108)+2),$D$1:$V$1,0)) -> 129 | AL108: =INDEX($D108:$V108,MATCH((YEAR($C108)+3),$D$1:$V$1,0)) -> 139 | AM108: =INDEX($D108:$V108,MATCH((YEAR($C108)+4),$D$1:$V$1,0)) -> 137
A109: 0.0074 | B109: 0.0028 | C109: 45261 | L109: 111 | M109: 116 | N109: 144 | O109: 154 | P109: 153 | Q109: 161 | R109: =Q109-2 -> 159 | S109: =R109-2 -> 157 | T109: =S109-2 -> 155 | W109: =((13-MONTH($C109))*INDEX($D109:$V109,1,MATCH(YEAR($C109),$D$1:$V$1,0))+12*INDEX($D109:$V109,1,MATCH(YEAR($C109)+1,$D$1:$V$1,0))+12*INDEX($D109:$V109,1,MATCH(YEAR($C109)+2,$D$1:$V$1,0))+(MONTH($C109)-1)*INDEX($D109:$V109,1,MATCH(YEAR($C109)+3,$D$1:$V$1,0)))/36 -> 136.80556 | X109: =AVERAGE($W$2:$W$198) -> 205.00794 | Y109: =((13-MONTH($C109))*INDEX($D109:$V109,1,MATCH(YEAR($C109),$D$1:$V$1,0))+12*INDEX($D109:$V109,1,MATCH(YEAR($C109)+1,$D$1:$V$1,0))+12*INDEX($D109:$V109,1,MATCH(YEAR($C109)+2,$D$1:$V$1,0))+12*INDEX($D109:$V109,1,MATCH(YEAR($C109)+3,$D$1:$V$1,0))+12*INDEX($D109:$V109,1,MATCH(YEAR($C109)+4,$D$1:$V$1,0))+(MONTH($C109)-1)*INDEX($D109:$V109,1,MATCH(YEAR($C109)+5,$D$1:$V$1,0)))/60 -> 144.76667 | Z109: =AVERAGE($Y$2:$Y$198) -> 198.26369 | AA109: 29.89 | AB109: 65 | AC109: 97.95 | AD109: 330 | AE109: =$AD109+$AA109 -> 359.89 | AF109: =$AD109+$AB109 -> 395 | AG109: =$AD109+$AC109 -> 427.95 | AH109: =(AD109-W109)/AD109 -> 0.58543771 | AI109: =INDEX($D109:$V109,MATCH(YEAR($C109),$D$1:$V$1,0)) -> 111 | AJ109: =INDEX($D109:$V109,MATCH((YEAR($C109)+1),$D$1:$V$1,0)) -> 116 | AK109: =INDEX($D109:$V109,MATCH((YEAR($C109)+2),$D$1:$V$1,0)) -> 144 | AL109: =INDEX($D109:$V109,MATCH((YEAR($C109)+3),$D$1:$V$1,0)) -> 154 | AM109: =INDEX($D109:$V109,MATCH((YEAR($C109)+4),$D$1:$V$1,0)) -> 153
A110: 0.0007 | B110: 0.0042 | C110: 45292 | M110: 120 | N110: 135 | O110: 147 | P110: 168 | Q110: 167 | R110: =Q110-2 -> 165 | S110: =R110-2 -> 163 | T110: =S110-2 -> 161 | W110: =((13-MONTH($C110))*INDEX($D110:$V110,1,MATCH(YEAR($C110),$D$1:$V$1,0))+12*INDEX($D110:$V110,1,MATCH(YEAR($C110)+1,$D$1:$V$1,0))+12*INDEX($D110:$V110,1,MATCH(YEAR($C110)+2,$D$1:$V$1,0))+(MONTH($C110)-1)*INDEX($D110:$V110,1,MATCH(YEAR($C110)+3,$D$1:$V$1,0)))/36 -> 134 | X110: =AVERAGE($W$2:$W$198) -> 205.00794 | Y110: =((13-MONTH($C110))*INDEX($D110:$V110,1,MATCH(YEAR($C110),$D$1:$V$1,0))+12*INDEX($D110:$V110,1,MATCH(YEAR($C110)+1,$D$1:$V$1,0))+12*INDEX($D110:$V110,1,MATCH(YEAR($C110)+2,$D$1:$V$1,0))+12*INDEX($D110:$V110,1,MATCH(YEAR($C110)+3,$D$1:$V$1,0))+12*INDEX($D110:$V110,1,MATCH(YEAR($C110)+4,$D$1:$V$1,0))+(MONTH($C110)-1)*INDEX($D110:$V110,1,MATCH(YEAR($C110)+5,$D$1:$V$1,0)))/60 -> 147.4 | Z110: =AVERAGE($Y$2:$Y$198) -> 198.26369 | AA110: 18.85 | AB110: 44.63 | AC110: 78.77 | AD110: 350 | AE110: =$AD110+$AA110 -> 368.85 | AF110: =$AD110+$AB110 -> 394.63 | AG110: =$AD110+$AC110 -> 428.77 | AH110: =(AD110-W110)/AD110 -> 0.61714286 | AI110: =INDEX($D110:$V110,MATCH(YEAR($C110),$D$1:$V$1,0)) -> 120 | AJ110: =INDEX($D110:$V110,MATCH((YEAR($C110)+1),$D$1:$V$1,0)) -> 135 | AK110: =INDEX($D110:$V110,MATCH((YEAR($C110)+2),$D$1:$V$1,0)) -> 147 | AL110: =INDEX($D110:$V110,MATCH((YEAR($C110)+3),$D$1:$V$1,0)) -> 168 | AM110: =INDEX($D110:$V110,MATCH((YEAR($C110)+4),$D$1:$V$1,0)) -> 167
A111: -0.0052 | B111: 0.0083 | C111: 45323 | M111: 159 | N111: 216 | O111: 207 | P111: 201 | Q111: 191 | R111: 185 | S111: =R111-5 -> 180 | T111: =S111-5 -> 175 | W111: =((13-MONTH($C111))*INDEX($D111:$V111,1,MATCH(YEAR($C111),$D$1:$V$1,0))+12*INDEX($D111:$V111,1,MATCH(YEAR($C111)+1,$D$1:$V$1,0))+12*INDEX($D111:$V111,1,MATCH(YEAR($C111)+2,$D$1:$V$1,0))+(MONTH($C111)-1)*INDEX($D111:$V111,1,MATCH(YEAR($C111)+3,$D$1:$V$1,0)))/36 -> 195.16667 | X111: =AVERAGE($W$2:$W$198) -> 205.00794 | Y111: =((13-MONTH($C111))*INDEX($D111:$V111,1,MATCH(YEAR($C111),$D$1:$V$1,0))+12*INDEX($D111:$V111,1,MATCH(YEAR($C111)+1,$D$1:$V$1,0))+12*INDEX($D111:$V111,1,MATCH(YEAR($C111)+2,$D$1:$V$1,0))+12*INDEX($D111:$V111,1,MATCH(YEAR($C111)+3,$D$1:$V$1,0))+12*INDEX($D111:$V111,1,MATCH(YEAR($C111)+4,$D$1:$V$1,0))+(MONTH($C111)-1)*INDEX($D111:$V111,1,MATCH(YEAR($C111)+5,$D$1:$V$1,0)))/60 -> 195.23333 | Z111: =AVERAGE($Y$2:$Y$198) -> 198.26369 | AA111: 18.85 | AB111: 44.63 | AC111: 78.77 | AD111: 350 | AE111: =$AD111+$AA111 -> 368.85 | AF111: =$AD111+$AB111 -> 394.63 | AG111: =$AD111+$AC111 -> 428.77 | AH111: =(AD111-W111)/AD111 -> 0.44238095 | AI111: =INDEX($D111:$V111,MATCH(YEAR($C111),$D$1:$V$1,0)) -> 159 | AJ111: =INDEX($D111:$V111,MATCH((YEAR($C111)+1),$D$1:$V$1,0)) -> 216 | AK111: =INDEX($D111:$V111,MATCH((YEAR($C111)+2),$D$1:$V$1,0)) -> 207 | AL111: =INDEX($D111:$V111,MATCH((YEAR($C111)+3),$D$1:$V$1,0)) -> 201 | AM111: =INDEX($D111:$V111,MATCH((YEAR($C111)+4),$D$1:$V$1,0)) -> 191
A112: -0.0047 | B112: 0.0016 | C112: 45352 | M112: 159 | N112: 201 | O112: 195 | P112: 189 | Q112: 190 | R112: 186 | S112: =R112-5 -> 181 | T112: =S112-5 -> 176 | W112: =((13-MONTH($C112))*INDEX($D112:$V112,1,MATCH(YEAR($C112),$D$1:$V$1,0))+12*INDEX($D112:$V112,1,MATCH(YEAR($C112)+1,$D$1:$V$1,0))+12*INDEX($D112:$V112,1,MATCH(YEAR($C112)+2,$D$1:$V$1,0))+(MONTH($C112)-1)*INDEX($D112:$V112,1,MATCH(YEAR($C112)+3,$D$1:$V$1,0)))/36 -> 186.66667 | X112: =AVERAGE($W$2:$W$198) -> 205.00794 | Y112: =((13-MONTH($C112))*INDEX($D112:$V112,1,MATCH(YEAR($C112),$D$1:$V$1,0))+12*INDEX($D112:$V112,1,MATCH(YEAR($C112)+1,$D$1:$V$1,0))+12*INDEX($D112:$V112,1,MATCH(YEAR($C112)+2,$D$1:$V$1,0))+12*INDEX($D112:$V112,1,MATCH(YEAR($C112)+3,$D$1:$V$1,0))+12*INDEX($D112:$V112,1,MATCH(YEAR($C112)+4,$D$1:$V$1,0))+(MONTH($C112)-1)*INDEX($D112:$V112,1,MATCH(YEAR($C112)+5,$D$1:$V$1,0)))/60 -> 187.7 | Z112: =AVERAGE($Y$2:$Y$198) -> 198.26369 | AA112: 18.85 | AB112: 44.63 | AC112: 78.77 | AD112: 350 | AE112: =$AD112+$AA112 -> 368.85 | AF112: =$AD112+$AB112 -> 394.63 | AG112: =$AD112+$AC112 -> 428.77 | AH112: =(AD112-W112)/AD112 -> 0.46666667 | AI112: =INDEX($D112:$V112,MATCH(YEAR($C112),$D$1:$V$1,0)) -> 159 | AJ112: =INDEX($D112:$V112,MATCH((YEAR($C112)+1),$D$1:$V$1,0)) -> 201 | AK112: =INDEX($D112:$V112,MATCH((YEAR($C112)+2),$D$1:$V$1,0)) -> 195 | AL112: =INDEX($D112:$V112,MATCH((YEAR($C112)+3),$D$1:$V$1,0)) -> 189 | AM112: =INDEX($D112:$V112,MATCH((YEAR($C112)+4),$D$1:$V$1,0)) -> 190
A113: 0.0031 | B113: 0.0038 | C113: 45383 | M113: 150 | N113: 185 | O113: 186 | P113: 182 | Q113: =P113-5 -> 177 | R113: =Q113-5 -> 172 | S113: =R113-5 -> 167 | T113: =S113-5 -> 162 | W113: =((13-MONTH($C113))*INDEX($D113:$V113,1,MATCH(YEAR($C113),$D$1:$V$1,0))+12*INDEX($D113:$V113,1,MATCH(YEAR($C113)+1,$D$1:$V$1,0))+12*INDEX($D113:$V113,1,MATCH(YEAR($C113)+2,$D$1:$V$1,0))+(MONTH($C113)-1)*INDEX($D113:$V113,1,MATCH(YEAR($C113)+3,$D$1:$V$1,0)))/36 -> 176.33333 | X113: =AVERAGE($W$2:$W$198) -> 205.00794 | Y113: =((13-MONTH($C113))*INDEX($D113:$V113,1,MATCH(YEAR($C113),$D$1:$V$1,0))+12*INDEX($D113:$V113,1,MATCH(YEAR($C113)+1,$D$1:$V$1,0))+12*INDEX($D113:$V113,1,MATCH(YEAR($C113)+2,$D$1:$V$1,0))+12*INDEX($D113:$V113,1,MATCH(YEAR($C113)+3,$D$1:$V$1,0))+12*INDEX($D113:$V113,1,MATCH(YEAR($C113)+4,$D$1:$V$1,0))+(MONTH($C113)-1)*INDEX($D113:$V113,1,MATCH(YEAR($C113)+5,$D$1:$V$1,0)))/60 -> 177.1 | Z113: =AVERAGE($Y$2:$Y$198) -> 198.26369 | AA113: 18.85 | AB113: 44.63 | AC113: 78.77 | AD113: 350 | AE113: =$AD113+$AA113 -> 368.85 | AF113: =$AD113+$AB113 -> 394.63 | AG113: =$AD113+$AC113 -> 428.77 | AH113: =(AD113-W113)/AD113 -> 0.49619048 | AI113: =INDEX($D113:$V113,MATCH(YEAR($C113),$D$1:$V$1,0)) -> 150 | AJ113: =INDEX($D113:$V113,MATCH((YEAR($C113)+1),$D$1:$V$1,0)) -> 185 | AK113: =INDEX($D113:$V113,MATCH((YEAR($C113)+2),$D$1:$V$1,0)) -> 186 | AL113: =INDEX($D113:$V113,MATCH((YEAR($C113)+3),$D$1:$V$1,0)) -> 182 | AM113: =INDEX($D113:$V113,MATCH((YEAR($C113)+4),$D$1:$V$1,0)) -> 177
A114: 0.0089 | B114: 0.0046 | C114: 45413 | M114: 120 | N114: 160 | O114: 175 | P114: 172 | Q114: =P114-5 -> 167 | R114: =Q114-5 -> 162 | S114: =R114-5 -> 157 | T114: =S114-5 -> 152 | W114: =((13-MONTH($C114))*INDEX($D114:$V114,1,MATCH(YEAR($C114),$D$1:$V$1,0))+12*INDEX($D114:$V114,1,MATCH(YEAR($C114)+1,$D$1:$V$1,0))+12*INDEX($D114:$V114,1,MATCH(YEAR($C114)+2,$D$1:$V$1,0))+(MONTH($C114)-1)*INDEX($D114:$V114,1,MATCH(YEAR($C114)+3,$D$1:$V$1,0)))/36 -> 157.44444 | X114: =AVERAGE($W$2:$W$198) -> 205.00794 | Y114: =((13-MONTH($C114))*INDEX($D114:$V114,1,MATCH(YEAR($C114),$D$1:$V$1,0))+12*INDEX($D114:$V114,1,MATCH(YEAR($C114)+1,$D$1:$V$1,0))+12*INDEX($D114:$V114,1,MATCH(YEAR($C114)+2,$D$1:$V$1,0))+12*INDEX($D114:$V114,1,MATCH(YEAR($C114)+3,$D$1:$V$1,0))+12*INDEX($D114:$V114,1,MATCH(YEAR($C114)+4,$D$1:$V$1,0))+(MONTH($C114)-1)*INDEX($D114:$V114,1,MATCH(YEAR($C114)+5,$D$1:$V$1,0)))/60 -> 161.6 | Z114: =AVERAGE($Y$2:$Y$198) -> 198.26369 | AA114: 18.85 | AB114: 44.63 | AC114: 78.77 | AD114: 350 | AE114: =$AD114+$AA114 -> 368.85 | AF114: =$AD114+$AB114 -> 394.63 | AG114: =$AD114+$AC114 -> 428.77 | AH114: =(AD114-W114)/AD114 -> 0.55015873 | AI114: =INDEX($D114:$V114,MATCH(YEAR($C114),$D$1:$V$1,0)) -> 120 | AJ114: =INDEX($D114:$V114,MATCH((YEAR($C114)+1),$D$1:$V$1,0)) -> 160 | AK114: =INDEX($D114:$V114,MATCH((YEAR($C114)+2),$D$1:$V$1,0)) -> 175 | AL114: =INDEX($D114:$V114,MATCH((YEAR($C114)+3),$D$1:$V$1,0)) -> 172 | AM114: =INDEX($D114:$V114,MATCH((YEAR($C114)+4),$D$1:$V$1,0)) -> 167
A115: 0.0081 | B115: 0.0021 | C115: 45444 | M115: 172 | N115: 187 | O115: 188 | P115: 180 | Q115: =P115-5 -> 175 | R115: =Q115-5 -> 170 | S115: =R115-5 -> 165 | T115: =S115-5 -> 160 | W115: =((13-MONTH($C115))*INDEX($D115:$V115,1,MATCH(YEAR($C115),$D$1:$V$1,0))+12*INDEX($D115:$V115,1,MATCH(YEAR($C115)+1,$D$1:$V$1,0))+12*INDEX($D115:$V115,1,MATCH(YEAR($C115)+2,$D$1:$V$1,0))+(MONTH($C115)-1)*INDEX($D115:$V115,1,MATCH(YEAR($C115)+3,$D$1:$V$1,0)))/36 -> 183.44444 | X115: =AVERAGE($W$2:$W$198) -> 205.00794 | Y115: =((13-MONTH($C115))*INDEX($D115:$V115,1,MATCH(YEAR($C115),$D$1:$V$1,0))+12*INDEX($D115:$V115,1,MATCH(YEAR($C115)+1,$D$1:$V$1,0))+12*INDEX($D115:$V115,1,MATCH(YEAR($C115)+2,$D$1:$V$1,0))+12*INDEX($D115:$V115,1,MATCH(YEAR($C115)+3,$D$1:$V$1,0))+12*INDEX($D115:$V115,1,MATCH(YEAR($C115)+4,$D$1:$V$1,0))+(MONTH($C115)-1)*INDEX($D115:$V115,1,MATCH(YEAR($C115)+5,$D$1:$V$1,0)))/60 -> 180.23333 | Z115: =AVERAGE($Y$2:$Y$198) -> 198.26369 | AA115: 18.85 | AB115: 44.63 | AC115: 78.77 | AD115: 350 | AE115: =$AD115+$AA115 -> 368.85 | AF115: =$AD115+$AB115 -> 394.63 | AG115: =$AD115+$AC115 -> 428.77 | AH115: =(AD115-W115)/AD115 -> 0.47587302 | AI115: =INDEX($D115:$V115,MATCH(YEAR($C115),$D$1:$V$1,0)) -> 172 | AJ115: =INDEX($D115:$V115,MATCH((YEAR($C115)+1),$D$1:$V$1,0)) -> 187 | AK115: =INDEX($D115:$V115,MATCH((YEAR($C115)+2),$D$1:$V$1,0)) -> 188 | AL115: =INDEX($D115:$V115,MATCH((YEAR($C115)+3),$D$1:$V$1,0)) -> 180 | AM115: =INDEX($D115:$V115,MATCH((YEAR($C115)+4),$D$1:$V$1,0)) -> 175
A116: 0.0061 | B116: 0.0038 | C116: 45474 | M116: 230 | N116: 212 | O116: 197 | P116: 181 | Q116: =P116-5 -> 176 | R116: =Q116-5 -> 171 | S116: =R116-5 -> 166 | T116: =S116-5 -> 161 | W116: =((13-MONTH($C116))*INDEX($D116:$V116,1,MATCH(YEAR($C116),$D$1:$V$1,0))+12*INDEX($D116:$V116,1,MATCH(YEAR($C116)+1,$D$1:$V$1,0))+12*INDEX($D116:$V116,1,MATCH(YEAR($C116)+2,$D$1:$V$1,0))+(MONTH($C116)-1)*INDEX($D116:$V116,1,MATCH(YEAR($C116)+3,$D$1:$V$1,0)))/36 -> 204.83333 | X116: =AVERAGE($W$2:$W$198) -> 205.00794 | Y116: =((13-MONTH($C116))*INDEX($D116:$V116,1,MATCH(YEAR($C116),$D$1:$V$1,0))+12*INDEX($D116:$V116,1,MATCH(YEAR($C116)+1,$D$1:$V$1,0))+12*INDEX($D116:$V116,1,MATCH(YEAR($C116)+2,$D$1:$V$1,0))+12*INDEX($D116:$V116,1,MATCH(YEAR($C116)+3,$D$1:$V$1,0))+12*INDEX($D116:$V116,1,MATCH(YEAR($C116)+4,$D$1:$V$1,0))+(MONTH($C116)-1)*INDEX($D116:$V116,1,MATCH(YEAR($C116)+5,$D$1:$V$1,0)))/60 -> 193.3 | Z116: =AVERAGE($Y$2:$Y$198) -> 198.26369 | AA116: 18.85 | AB116: 44.63 | AC116: 78.77 | AD116: 350 | AE116: =$AD116+$AA116 -> 368.85 | AF116: =$AD116+$AB116 -> 394.63 | AG116: =$AD116+$AC116 -> 428.77 | AH116: =(AD116-W116)/AD116 -> 0.4147619 | AI116: =INDEX($D116:$V116,MATCH(YEAR($C116),$D$1:$V$1,0)) -> 230 | AJ116: =INDEX($D116:$V116,MATCH((YEAR($C116)+1),$D$1:$V$1,0)) -> 212 | AK116: =INDEX($D116:$V116,MATCH((YEAR($C116)+2),$D$1:$V$1,0)) -> 197 | AL116: =INDEX($D116:$V116,MATCH((YEAR($C116)+3),$D$1:$V$1,0)) -> 181 | AM116: =INDEX($D116:$V116,MATCH((YEAR($C116)+4),$D$1:$V$1,0)) -> 176
A117: 0.0029 | B117: 0.0019 | C117: 45505 | M117: 185 | N117: 202 | O117: 192 | P117: 180 | Q117: =P117-5 -> 175 | R117: =Q117-5 -> 170 | S117: =R117-5 -> 165 | T117: =S117-5 -> 160 | W117: =((13-MONTH($C117))*INDEX($D117:$V117,1,MATCH(YEAR($C117),$D$1:$V$1,0))+12*INDEX($D117:$V117,1,MATCH(YEAR($C117)+1,$D$1:$V$1,0))+12*INDEX($D117:$V117,1,MATCH(YEAR($C117)+2,$D$1:$V$1,0))+(MONTH($C117)-1)*INDEX($D117:$V117,1,MATCH(YEAR($C117)+3,$D$1:$V$1,0)))/36 -> 192.02778 | X117: =AVERAGE($W$2:$W$198) -> 205.00794 | Y117: =((13-MONTH($C117))*INDEX($D117:$V117,1,MATCH(YEAR($C117),$D$1:$V$1,0))+12*INDEX($D117:$V117,1,MATCH(YEAR($C117)+1,$D$1:$V$1,0))+12*INDEX($D117:$V117,1,MATCH(YEAR($C117)+2,$D$1:$V$1,0))+12*INDEX($D117:$V117,1,MATCH(YEAR($C117)+3,$D$1:$V$1,0))+12*INDEX($D117:$V117,1,MATCH(YEAR($C117)+4,$D$1:$V$1,0))+(MONTH($C117)-1)*INDEX($D117:$V117,1,MATCH(YEAR($C117)+5,$D$1:$V$1,0)))/60 -> 185.05 | Z117: =AVERAGE($Y$2:$Y$198) -> 198.26369 | AA117: 18.85 | AB117: 44.63 | AC117: 78.77 | AD117: 350 | AE117: =$AD117+$AA117 -> 368.85 | AF117: =$AD117+$AB117 -> 394.63 | AG117: =$AD117+$AC117 -> 428.77 | AH117: =(AD117-W117)/AD117 -> 0.45134921 | AI117: =INDEX($D117:$V117,MATCH(YEAR($C117),$D$1:$V$1,0)) -> 185 | AJ117: =INDEX($D117:$V117,MATCH((YEAR($C117)+1),$D$1:$V$1,0)) -> 202 | AK117: =INDEX($D117:$V117,MATCH((YEAR($C117)+2),$D$1:$V$1,0)) -> 192 | AL117: =INDEX($D117:$V117,MATCH((YEAR($C117)+3),$D$1:$V$1,0)) -> 180 | AM117: =INDEX($D117:$V117,MATCH((YEAR($C117)+4),$D$1:$V$1,0)) -> 175
A118: 0.0062 | B118: 0.0044 | C118: 45536 | M118: 228 | N118: 216 | O118: 200 | P118: 183 | Q118: =P118-5 -> 178 | R118: =Q118-5 -> 173 | S118: =R118-5 -> 168 | T118: =S118-5 -> 163 | W118: =((13-MONTH($C118))*INDEX($D118:$V118,1,MATCH(YEAR($C118),$D$1:$V$1,0))+12*INDEX($D118:$V118,1,MATCH(YEAR($C118)+1,$D$1:$V$1,0))+12*INDEX($D118:$V118,1,MATCH(YEAR($C118)+2,$D$1:$V$1,0))+(MONTH($C118)-1)*INDEX($D118:$V118,1,MATCH(YEAR($C118)+3,$D$1:$V$1,0)))/36 -> 204.66667 | X118: =AVERAGE($W$2:$W$198) -> 205.00794 | Y118: =((13-MONTH($C118))*INDEX($D118:$V118,1,MATCH(YEAR($C118),$D$1:$V$1,0))+12*INDEX($D118:$V118,1,MATCH(YEAR($C118)+1,$D$1:$V$1,0))+12*INDEX($D118:$V118,1,MATCH(YEAR($C118)+2,$D$1:$V$1,0))+12*INDEX($D118:$V118,1,MATCH(YEAR($C118)+3,$D$1:$V$1,0))+12*INDEX($D118:$V118,1,MATCH(YEAR($C118)+4,$D$1:$V$1,0))+(MONTH($C118)-1)*INDEX($D118:$V118,1,MATCH(YEAR($C118)+5,$D$1:$V$1,0)))/60 -> 193.66667 | Z118: =AVERAGE($Y$2:$Y$198) -> 198.26369 | AA118: 18.85 | AB118: 44.63 | AC118: 78.77 | AD118: 350 | AE118: =$AD118+$AA118 -> 368.85 | AF118: =$AD118+$AB118 -> 394.63 | AG118: =$AD118+$AC118 -> 428.77 | AH118: =(AD118-W118)/AD118 -> 0.4152381 | AI118: =INDEX($D118:$V118,MATCH(YEAR($C118),$D$1:$V$1,0)) -> 228 | AJ118: =INDEX($D118:$V118,MATCH((YEAR($C118)+1),$D$1:$V$1,0)) -> 216 | AK118: =INDEX($D118:$V118,MATCH((YEAR($C118)+2),$D$1:$V$1,0)) -> 200 | AL118: =INDEX($D118:$V118,MATCH((YEAR($C118)+3),$D$1:$V$1,0)) -> 183 | AM118: =INDEX($D118:$V118,MATCH((YEAR($C118)+4),$D$1:$V$1,0)) -> 178
A119: 0.0152 | B119: 0.0054 | C119: 45566 | M119: 320 | N119: 243 | O119: 201 | P119: 181 | Q119: =P119-5 -> 176 | R119: =Q119-5 -> 171 | S119: =R119-5 -> 166 | T119: =S119-5 -> 161 | W119: =((13-MONTH($C119))*INDEX($D119:$V119,1,MATCH(YEAR($C119),$D$1:$V$1,0))+12*INDEX($D119:$V119,1,MATCH(YEAR($C119)+1,$D$1:$V$1,0))+12*INDEX($D119:$V119,1,MATCH(YEAR($C119)+2,$D$1:$V$1,0))+(MONTH($C119)-1)*INDEX($D119:$V119,1,MATCH(YEAR($C119)+3,$D$1:$V$1,0)))/36 -> 219.91667 | X119: =AVERAGE($W$2:$W$198) -> 205.00794 | Y119: =((13-MONTH($C119))*INDEX($D119:$V119,1,MATCH(YEAR($C119),$D$1:$V$1,0))+12*INDEX($D119:$V119,1,MATCH(YEAR($C119)+1,$D$1:$V$1,0))+12*INDEX($D119:$V119,1,MATCH(YEAR($C119)+2,$D$1:$V$1,0))+12*INDEX($D119:$V119,1,MATCH(YEAR($C119)+3,$D$1:$V$1,0))+12*INDEX($D119:$V119,1,MATCH(YEAR($C119)+4,$D$1:$V$1,0))+(MONTH($C119)-1)*INDEX($D119:$V119,1,MATCH(YEAR($C119)+5,$D$1:$V$1,0)))/60 -> 201.85 | Z119: =AVERAGE($Y$2:$Y$198) -> 198.26369 | AA119: 18.85 | AB119: 44.63 | AC119: 78.77 | AD119: 350 | AE119: =$AD119+$AA119 -> 368.85 | AF119: =$AD119+$AB119 -> 394.63 | AG119: =$AD119+$AC119 -> 428.77 | AH119: =(AD119-W119)/AD119 -> 0.37166667 | AI119: =INDEX($D119:$V119,MATCH(YEAR($C119),$D$1:$V$1,0)) -> 320 | AJ119: =INDEX($D119:$V119,MATCH((YEAR($C119)+1),$D$1:$V$1,0)) -> 243 | AK119: =INDEX($D119:$V119,MATCH((YEAR($C119)+2),$D$1:$V$1,0)) -> 201 | AL119: =INDEX($D119:$V119,MATCH((YEAR($C119)+3),$D$1:$V$1,0)) -> 181 | AM119: =INDEX($D119:$V119,MATCH((YEAR($C119)+4),$D$1:$V$1,0)) -> 176
A120: 0.013 | B120: 0.0039 | C120: 45597 | M120: 282 | N120: 176 | O120: 189 | P120: 178 | Q120: =P120-5 -> 173 | R120: =Q120-5 -> 168 | S120: =R120-5 -> 163 | T120: =S120-5 -> 158 | W120: =((13-MONTH($C120))*INDEX($D120:$V120,1,MATCH(YEAR($C120),$D$1:$V$1,0))+12*INDEX($D120:$V120,1,MATCH(YEAR($C120)+1,$D$1:$V$1,0))+12*INDEX($D120:$V120,1,MATCH(YEAR($C120)+2,$D$1:$V$1,0))+(MONTH($C120)-1)*INDEX($D120:$V120,1,MATCH(YEAR($C120)+3,$D$1:$V$1,0)))/36 -> 186.77778 | X120: =AVERAGE($W$2:$W$198) -> 205.00794 | Y120: =((13-MONTH($C120))*INDEX($D120:$V120,1,MATCH(YEAR($C120),$D$1:$V$1,0))+12*INDEX($D120:$V120,1,MATCH(YEAR($C120)+1,$D$1:$V$1,0))+12*INDEX($D120:$V120,1,MATCH(YEAR($C120)+2,$D$1:$V$1,0))+12*INDEX($D120:$V120,1,MATCH(YEAR($C120)+3,$D$1:$V$1,0))+12*INDEX($D120:$V120,1,MATCH(YEAR($C120)+4,$D$1:$V$1,0))+(MONTH($C120)-1)*INDEX($D120:$V120,1,MATCH(YEAR($C120)+5,$D$1:$V$1,0)))/60 -> 180.6 | Z120: =AVERAGE($Y$2:$Y$198) -> 198.26369 | AA120: 18.85 | AB120: 44.63 | AC120: 78.77 | AD120: 350 | AE120: =$AD120+$AA120 -> 368.85 | AF120: =$AD120+$AB120 -> 394.63 | AG120: =$AD120+$AC120 -> 428.77 | AH120: =(AD120-W120)/AD120 -> 0.46634921 | AI120: =INDEX($D120:$V120,MATCH(YEAR($C120),$D$1:$V$1,0)) -> 282 | AJ120: =INDEX($D120:$V120,MATCH((YEAR($C120)+1),$D$1:$V$1,0)) -> 176 | AK120: =INDEX($D120:$V120,MATCH((YEAR($C120)+2),$D$1:$V$1,0)) -> 189 | AL120: =INDEX($D120:$V120,MATCH((YEAR($C120)+3),$D$1:$V$1,0)) -> 178 | AM120: =INDEX($D120:$V120,MATCH((YEAR($C120)+4),$D$1:$V$1,0)) -> 173
A121: 0.0094 | B121: 0.0052 | C121: 45627 | M121: 117 | N121: 180 | O121: 191 | P121: 186 | Q121: =P121-5 -> 181 | R121: =Q121-5 -> 176 | S121: =R121-5 -> 171 | T121: =S121-5 -> 166 | W121: =((13-MONTH($C121))*INDEX($D121:$V121,1,MATCH(YEAR($C121),$D$1:$V$1,0))+12*INDEX($D121:$V121,1,MATCH(YEAR($C121)+1,$D$1:$V$1,0))+12*INDEX($D121:$V121,1,MATCH(YEAR($C121)+2,$D$1:$V$1,0))+(MONTH($C121)-1)*INDEX($D121:$V121,1,MATCH(YEAR($C121)+3,$D$1:$V$1,0)))/36 -> 183.75 | X121: =AVERAGE($W$2:$W$198) -> 205.00794 | Y121: =((13-MONTH($C121))*INDEX($D121:$V121,1,MATCH(YEAR($C121),$D$1:$V$1,0))+12*INDEX($D121:$V121,1,MATCH(YEAR($C121)+1,$D$1:$V$1,0))+12*INDEX($D121:$V121,1,MATCH(YEAR($C121)+2,$D$1:$V$1,0))+12*INDEX($D121:$V121,1,MATCH(YEAR($C121)+3,$D$1:$V$1,0))+12*INDEX($D121:$V121,1,MATCH(YEAR($C121)+4,$D$1:$V$1,0))+(MONTH($C121)-1)*INDEX($D121:$V121,1,MATCH(YEAR($C121)+5,$D$1:$V$1,0)))/60 -> 181.81667 | Z121: =AVERAGE($Y$2:$Y$198) -> 198.26369 | AA121: 18.85 | AB121: 44.63 | AC121: 78.77 | AD121: 350 | AE121: =$AD121+$AA121 -> 368.85 | AF121: =$AD121+$AB121 -> 394.63 | AG121: =$AD121+$AC121 -> 428.77 | AH121: =(AD121-W121)/AD121 -> 0.475 | AI121: =INDEX($D121:$V121,MATCH(YEAR($C121),$D$1:$V$1,0)) -> 117 | AJ121: =INDEX($D121:$V121,MATCH((YEAR($C121)+1),$D$1:$V$1,0)) -> 180 | AK121: =INDEX($D121:$V121,MATCH((YEAR($C121)+2),$D$1:$V$1,0)) -> 191 | AL121: =INDEX($D121:$V121,MATCH((YEAR($C121)+3),$D$1:$V$1,0)) -> 186 | AM121: =INDEX($D121:$V121,MATCH((YEAR($C121)+4),$D$1:$V$1,0)) -> 181
A122: 0.0027 | B122: 0.0016 | C122: 45658 | N122: 175 | O122: 199 | P122: 180 | Q122: =P122-5 -> 175 | R122: =Q122-5 -> 170 | S122: =R122-5 -> 165 | T122: =S122-5 -> 160 | W122: =((13-MONTH($C122))*INDEX($D122:$V122,1,MATCH(YEAR($C122),$D$1:$V$1,0))+12*INDEX($D122:$V122,1,MATCH(YEAR($C122)+1,$D$1:$V$1,0))+12*INDEX($D122:$V122,1,MATCH(YEAR($C122)+2,$D$1:$V$1,0))+(MONTH($C122)-1)*INDEX($D122:$V122,1,MATCH(YEAR($C122)+3,$D$1:$V$1,0)))/36 -> 184.66667 | X122: =AVERAGE($W$2:$W$198) -> 205.00794 | Y122: =((13-MONTH($C122))*INDEX($D122:$V122,1,MATCH(YEAR($C122),$D$1:$V$1,0))+12*INDEX($D122:$V122,1,MATCH(YEAR($C122)+1,$D$1:$V$1,0))+12*INDEX($D122:$V122,1,MATCH(YEAR($C122)+2,$D$1:$V$1,0))+12*INDEX($D122:$V122,1,MATCH(YEAR($C122)+3,$D$1:$V$1,0))+12*INDEX($D122:$V122,1,MATCH(YEAR($C122)+4,$D$1:$V$1,0))+(MONTH($C122)-1)*INDEX($D122:$V122,1,MATCH(YEAR($C122)+5,$D$1:$V$1,0)))/60 -> 179.8 | Z122: =AVERAGE($Y$2:$Y$198) -> 198.26369 | AA122: 18.85 | AB122: 44.63 | AC122: 78.77 | AD122: 390 | AE122: =$AD122+$AA122 -> 408.85 | AF122: =$AD122+$AB122 -> 434.63 | AG122: =$AD122+$AC122 -> 468.77 | AH122: =(AD122-W122)/AD122 -> 0.52649573 | AI122: =INDEX($D122:$V122,MATCH(YEAR($C122),$D$1:$V$1,0)) -> 175 | AJ122: =INDEX($D122:$V122,MATCH((YEAR($C122)+1),$D$1:$V$1,0)) -> 199 | AK122: =INDEX($D122:$V122,MATCH((YEAR($C122)+2),$D$1:$V$1,0)) -> 180 | AL122: =INDEX($D122:$V122,MATCH((YEAR($C122)+3),$D$1:$V$1,0)) -> 175 | AM122: =INDEX($D122:$V122,MATCH((YEAR($C122)+4),$D$1:$V$1,0)) -> 170
A123: 0.0106 | B123: 0.0131 | C123: 45689 | N123: 227 | O123: 219 | P123: 198 | Q123: 183 | R123: =Q123-5 -> 178 | S123: =R123-5 -> 173 | T123: =S123-10 -> 163 | W123: =((13-MONTH($C123))*INDEX($D123:$V123,1,MATCH(YEAR($C123),$D$1:$V$1,0))+12*INDEX($D123:$V123,1,MATCH(YEAR($C123)+1,$D$1:$V$1,0))+12*INDEX($D123:$V123,1,MATCH(YEAR($C123)+2,$D$1:$V$1,0))+(MONTH($C123)-1)*INDEX($D123:$V123,1,MATCH(YEAR($C123)+3,$D$1:$V$1,0)))/36 -> 213.44444 | X123: =AVERAGE($W$2:$W$198) -> 205.00794 | Y123: =((13-MONTH($C123))*INDEX($D123:$V123,1,MATCH(YEAR($C123),$D$1:$V$1,0))+12*INDEX($D123:$V123,1,MATCH(YEAR($C123)+1,$D$1:$V$1,0))+12*INDEX($D123:$V123,1,MATCH(YEAR($C123)+2,$D$1:$V$1,0))+12*INDEX($D123:$V123,1,MATCH(YEAR($C123)+3,$D$1:$V$1,0))+12*INDEX($D123:$V123,1,MATCH(YEAR($C123)+4,$D$1:$V$1,0))+(MONTH($C123)-1)*INDEX($D123:$V123,1,MATCH(YEAR($C123)+5,$D$1:$V$1,0)))/60 -> 200.1 | Z123: =AVERAGE($Y$2:$Y$198) -> 198.26369 | AA123: 18.85 | AB123: 44.63 | AC123: 78.77 | AD123: 390 | AE123: =$AD123+$AA123 -> 408.85 | AF123: =$AD123+$AB123 -> 434.63 | AG123: =$AD123+$AC123 -> 468.77 | AH123: =(AD123-W123)/AD123 -> 0.45270655 | AI123: =INDEX($D123:$V123,MATCH(YEAR($C123),$D$1:$V$1,0)) -> 227 | AJ123: =INDEX($D123:$V123,MATCH((YEAR($C123)+1),$D$1:$V$1,0)) -> 219 | AK123: =INDEX($D123:$V123,MATCH((YEAR($C123)+2),$D$1:$V$1,0)) -> 198 | AL123: =INDEX($D123:$V123,MATCH((YEAR($C123)+3),$D$1:$V$1,0)) -> 183 | AM123: =INDEX($D123:$V123,MATCH((YEAR($C123)+4),$D$1:$V$1,0)) -> 178
A124: -0.0034 | B124: 0.0064 | C124: 45717 | N124: 322 | O124: 242 | P124: 206 | Q124: 191 | R124: =Q124-5 -> 186 | S124: =R124-5 -> 181 | T124: =S124-10 -> 171 | W124: =((13-MONTH($C124))*INDEX($D124:$V124,1,MATCH(YEAR($C124),$D$1:$V$1,0))+12*INDEX($D124:$V124,1,MATCH(YEAR($C124)+1,$D$1:$V$1,0))+12*INDEX($D124:$V124,1,MATCH(YEAR($C124)+2,$D$1:$V$1,0))+(MONTH($C124)-1)*INDEX($D124:$V124,1,MATCH(YEAR($C124)+3,$D$1:$V$1,0)))/36 -> 249.38889 | X124: =AVERAGE($W$2:$W$198) -> 205.00794 | Y124: =((13-MONTH($C124))*INDEX($D124:$V124,1,MATCH(YEAR($C124),$D$1:$V$1,0))+12*INDEX($D124:$V124,1,MATCH(YEAR($C124)+1,$D$1:$V$1,0))+12*INDEX($D124:$V124,1,MATCH(YEAR($C124)+2,$D$1:$V$1,0))+12*INDEX($D124:$V124,1,MATCH(YEAR($C124)+3,$D$1:$V$1,0))+12*INDEX($D124:$V124,1,MATCH(YEAR($C124)+4,$D$1:$V$1,0))+(MONTH($C124)-1)*INDEX($D124:$V124,1,MATCH(YEAR($C124)+5,$D$1:$V$1,0)))/60 -> 224.7 | Z124: =AVERAGE($Y$2:$Y$198) -> 198.26369 | AA124: 18.85 | AB124: 44.63 | AC124: 78.77 | AD124: 390 | AE124: =$AD124+$AA124 -> 408.85 | AF124: =$AD124+$AB124 -> 434.63 | AG124: =$AD124+$AC124 -> 468.77 | AH124: =(AD124-W124)/AD124 -> 0.36054131 | AI124: =INDEX($D124:$V124,MATCH(YEAR($C124),$D$1:$V$1,0)) -> 322 | AJ124: =INDEX($D124:$V124,MATCH((YEAR($C124)+1),$D$1:$V$1,0)) -> 242 | AK124: =INDEX($D124:$V124,MATCH((YEAR($C124)+2),$D$1:$V$1,0)) -> 206 | AL124: =INDEX($D124:$V124,MATCH((YEAR($C124)+3),$D$1:$V$1,0)) -> 191 | AM124: =INDEX($D124:$V124,MATCH((YEAR($C124)+4),$D$1:$V$1,0)) -> 186
...

Sheet Atac-I50-SECOeS
A1: IGPM | B1: IPCA | D1: 2015 | E1: 2016 | F1: 2017 | G1: 2018 | H1: 2019 | I1: 2020 | J1: 2021 | K1: 2022 | L1: 2023 | M1: 2024 | N1: 2025 | O1: 2026 | P1: 2027 | Q1: 2028 | R1: 2029 | S1: 2030 | T1: 2031 | U1: 2032 | V1: 2033 | W1: Preços Mercado Livre (I50% - 36 meses futuros) | X1: Preços Mercado Livre - Média Histórica ACL de 36 meses Futuros | Y1: Preços Mercado Livre (I50% - 60 meses futuros) | Z1: Preços Mercado Livre - Média Histórica ACL de 60 meses Futuros | AA1: Ágio Amarela | AB1: Ágio Verm I | AC1: Ágio Verm II | AD1: Break even - Bandeira Verde | AE1: Break even - Bandeira Verde | AF1: Break even - Bandeira Amarela | AG1: Break even - Bandeira Vermelha I | AH1: Break even - Bandeira Vermelha II | AI1: Economia R$/MWh | AJ1: % Economia (Livre x Cativo) | AK1: Positivo | AL1: Negativo | AM1: A+0 (atual 2026) | AN1: A+1 (atual 2027) | AO1: A+2 (atual 2028) | AP1: A+3 (atual 2029) | AQ1: A+4 (atual 2030)
